Workbook

Sheet Mode d'emploi
A1: Mode d'emploi
A2: LES TROIS REGISTRES
A3: Livre des recettes | B3: Obligatoire pour toute micro-entreprise. Une ligne par encaissement. C'est lui qui sert à la déclaration URSSAF.
A4: Registre des achats | B4: Obligatoire dès qu'il y a achat-revente. Une ligne par lot facturé, frais d'expédition compris.
A5: Objets mobiliers | B5: Obligatoire pour l'achat-revente de biens d'occasion — article 321-7 du code pénal. Tenue numérique admise depuis 2020.
A7: LA RÈGLE QUI PIÈGE LE PLUS
A8: Encaissé, pas vendu | B8: Le livre des recettes enregistre la date où l'argent arrive. Une vente conclue le 12 août et virée le 20 se déclare au 20 août. C'est le cas de la paire Salomon : vendue le 12/08, inscrite au 21/08, jour du virement Vinted.
A10: RÈGLES DE TENUE
A11: Ordre chronologique | B11: Les lignes se saisissent au fil de l'eau, dans l'ordre des dates.
A12: Jamais de suppression | B12: On ne supprime pas, on ne réordonne pas. Une erreur se corrige par une ligne rectificative.
A13: Numérotation continue | B13: Sans rupture. Le numéro se calcule tout seul dès qu'une date est saisie.
A14: Numérotation des factures | B14: Une seule série, continue, sans trou : 2026-001, 2026-002, 2026-003. Un numéro sauté ou réutilisé fait présumer une facture dissimulée. La première facture émise porte le n° 2026-001, vente à Mme Aouimeur Siham du 09/08/2026.
A15: Conservation | B15: 5 ans minimum. Garder les factures des maisons de vente, elles justifient chaque ligne.
A16: Sortie partielle | B16: Un lot vendu à l'unité se solde en plusieurs fois : le noter en observations jusqu'à épuisement.
A17: Prélèvement personnel | B17: Un article gardé pour soi sort du stock sans recette. Il ne s'inscrit pas au livre des recettes — il n'y a pas d'encaissement — mais il se note en sortie sur le registre des objets mobiliers, avec la mention « usage personnel ». Sans cette ligne, le stock ne tombe jamais juste.
A18: Le remboursement du prélèvement | B18: Remettre l'argent sur le compte pro n'est pas obligatoire — il n'y a qu'une personne juridique. Mais c'est une bonne pratique : sans ça, le stock fond et la caisse ne suit pas. Verser le COÛT D'ACHAT, pas le prix de vente : l'entreprise récupère ce qu'elle a payé, ni plus ni moins.
A19: Apport, pas recette | B19: Le virement du compte personnel vers le compte professionnel est un APPORT. Aucun chiffre d'affaires, aucune URSSAF, rien à déclarer. Le libeller « apport personnel » : sur un relevé pro, une somme qui arrive sans libellé ressemble à un encaissement client introuvable au livre des recettes.
A20: Apport enregistré | B20: 150,50 € versés en apport personnel, couvrant au coût les quatre prélèvements : Hoka 65,37 € + Nike 52,77 € + pompe Robby ligne 131 19,41 € + booster High Class 12,95 €.
A22: ENCAISSEMENT PAR PAYPAL
A23: Le montant à inscrire | B23: Le montant PAYÉ PAR LE CLIENT, jamais le montant versé par PayPal. Un client paie 89 €, PayPal en crédite ~86 € : la recette est de 89 € et les cotisations se calculent sur 89 €.
A24: La commission | B24: Elle ne se déduit nulle part. En micro-entreprise aucune charge n'est déductible : la commission PayPal sort de la marge, pas du chiffre d'affaires. Elle n'est pas une ligne du registre.
A25: Ce qu'on note | B25: Mode de règlement « PayPal », et en référence l'identifiant de transaction. C'est lui qui relie la ligne au relevé PayPal en cas de contrôle.
A26: Le solde PayPal | B26: PayPal est un compte de paiement, pas un compte bancaire. Virer le solde sur le compte professionnel au moins une fois par mois : tant qu'il y dort, ce n'est pas de la trésorerie disponible.
A27: Jamais « entre proches » | B27: Un acheteur qui propose de payer en friends and family fait disparaître la protection vendeur et déguise une vente commerciale. Refuser sans exception.
A29: VENTES EN ESPÈCES
A30: Plafond | B30: 1 000 € par transaction entre un professionnel et un particulier résidant en France — art. L112-6 du code monétaire et financier. Aucune vente n'en approche.
A31: La preuve | B31: Une note de vente par transaction : date, article, prix, nom de l'acheteur. Un carnet à souches suffit. C'est elle qui adosse la ligne du registre.
A32: Le dépôt | B32: Déposer directement sur le compte professionnel. Passer par le compte personnel puis virer casse le lien entre la vente et le relevé.
A34: DÉCLARATION URSSAF
A35: Ce qu'on déclare | B35: Le chiffre d'affaires encaissé sur la période. Total en haut à droite du livre des recettes.
A36: Taux | B36: 12,3 % de cotisations + 0,1 % de CFP = 12,4 %. À vérifier sur autoentrepreneur.urssaf.fr.
A37: Provision | B37: À virer sur un compte séparé à chaque encaissement, pas au trimestre.
A38: Pas de versement libératoire | B38: L'impôt suit le barème après abattement de 71 %. Il tombe l'année suivante — à provisionner aussi.
A40: CE QUI RESTE À COMPLÉTER
A41: Livre des recettes | B41: Complet. Quatre ventes à Mme Aouimeur Siham le 09/08 en espèces et main propre, deux paires de Havaianas sur Vinted encaissées le 10/08, la Salomon encaissée le 21/08, la New Balance Alkaline Green et une paire de Havaianas encaissées le 10/09.
A42: Ventes Vinted | B42: Sur un compte particulier, le vendeur ne paie pas de commission et l'acheteur paie le port : le prix affiché est encaissé en entier. Les fonds sont libérés après validation de la réception, c'est cette date-là qui compte au registre.
A43: Justifier une vente Vinted | B43: Vinted n'affiche AUCUN numéro de commande au vendeur. Le justificatif, c'est l'historique du porte-monnaie (Profil puis Solde) : date, montant, article. En faire une capture d'écran. Le numéro de suivi du colis et la conversation avec l'acheteur complètent la preuve.
A44: Relevé annuel DAC7 | B44: Vinted déclare au fisc les vendeurs dépassant 30 ventes ou 2 000 € par an, et envoie un relevé annuel récapitulatif vers janvier. Le conserver et VÉRIFIER QU'IL CONCORDE avec le livre des recettes : un écart entre ce que la plateforme déclare et ce que tu déclares est le premier déclencheur de contrôle.
A45: Exporter régulièrement | B45: Les plateformes ne gardent pas l'historique cinq ans, contrairement à l'obligation de conservation. Exporter les justificatifs en PDF ou en capture, dans un dossier daté.
A46: Plus aucune ligne jaune | B46: Tous les achats ont leur facture. Bordereau ERA n°507148 réglé en deux fois : 59,60 € le 28/07 et 24,00 € le 03/08/2026.
...

Sheet Livre des recettes
A1: Livre des recettes — Maison Nsaia
A2: Obligatoire pour toute micro-entreprise. Une ligne par encaissement, dans l'ordre chronologique.
A3: On inscrit la vente le jour où l'argent arrive, pas le jour où elle est conclue. Ne jamais supprimer ni réordonner une ligne. | K3: TOTAUX
K4: Recettes encaissées, total | L4: =SUM(E6:E311)
A5: N° | B5: Date d'encaissement | C5: Client | D5: Désignation | E5: Montant encaissé | F5: Mode de règlement | G5: Canal | H5: Référence / pièce justificative | I5: Nature de la recette | J5: Trimestre | K5: dont achat-revente | L5: =SUMIF(I6:I311,"Achat-revente",E6:E311)
A6: =IF(B6="","",ROW()-5) | B6: 09/08/2026 | C6: Mme Aouimeur Siham | D6: T-shirt BALENCIAGA T.2 | E6: 155 | F6: Espèces | G6: Main propre | H6: Facture n° 2026-001 | I6: Achat-revente | J6: =IF(B6="","",IFERROR(RIGHT(B6,4)&" T"&ROUNDUP(VALUE(MID(B6,4,2))/3,0),"")) | K6: dont prestations de services | L6: =SUMIF(I6:I311,"Prestation de services",E6:E311)
A7: =IF(B7="","",ROW()-5) | B7: 09/08/2026 | C7: Mme Aouimeur Siham | D7: Sac demi-lune KARL LAGERFELD JEANS | E7: 70 | F7: Espèces | G7: Main propre | H7: Facture n° 2026-001 | I7: Achat-revente | J7: =IF(B7="","",IFERROR(RIGHT(B7,4)&" T"&ROUNDUP(VALUE(MID(B7,4,2))/3,0),"")) | K7: dont convoyage automobile | L7: =SUMIF(I6:I311,"Convoyage automobile",E6:E311)
A8: =IF(B8="","",ROW()-5) | B8: 09/08/2026 | C8: Mme Aouimeur Siham | D8: LACOSTE sneakers P.42 | E8: 70 | F8: Espèces | G8: Main propre | H8: Facture n° 2026-001 | I8: Achat-revente | J8: =IF(B8="","",IFERROR(RIGHT(B8,4)&" T"&ROUNDUP(VALUE(MID(B8,4,2))/3,0),"")) | K8: URSSAF — 12,4 % revente · 21,3 % prestations et convoyage (taux à confirmer) | L8: =L5*0.124+(L6+L7)*0.213
A9: =IF(B9="","",ROW()-5) | B9: 09/08/2026 | C9: Mme Aouimeur Siham | D9: Veste en jean ARMANI EXCHANGE T.S | E9: 50 | F9: Espèces | G9: Main propre | H9: Facture n° 2026-001 | I9: Achat-revente | J9: =IF(B9="","",IFERROR(RIGHT(B9,4)&" T"&ROUNDUP(VALUE(MID(B9,4,2))/3,0),"")) | K9: Reste après URSSAF | L9: =L4-L8
A10: =IF(B10="","",ROW()-5) | B10: 10/08/2026 | C10: Natalie Gulitz — Offenbach am Main, Allemagne | D10: HAVAIANAS Slim 35/36 — 1 paire | E10: 14 | F10: Virement Vinted | G10: Vinted | H10: Vinted — suivi Chronopost XU173687375JF, expédiée le 03/08/2026 | I10: Achat-revente | J10: =IF(B10="","",IFERROR(RIGHT(B10,4)&" T"&ROUNDUP(VALUE(MID(B10,4,2))/3,0),"")) | K10: EN ATTENTE D'ENCAISSEMENT
A11: =IF(B11="","",ROW()-5) | B11: 10/08/2026 | C11: « colline_dvl » — pseudonyme Vinted | D11: HAVAIANAS Slim 35/36 — 1 paire | E11: 14 | F11: Virement Vinted | G11: Vinted | H11: Achat : FB2026-5844 lot n°120 | I11: Achat-revente | J11: =IF(B11="","",IFERROR(RIGHT(B11,4)&" T"&ROUNDUP(VALUE(MID(B11,4,2))/3,0),"")) | K11: BALLERINES MASSIMO DUTTI P.41 — vendues le 17/10/2026 sur Vinted à « anavdlr » | L11: 50
A12: =IF(B12="","",ROW()-5) | B12: 21/08/2026 | C12: Acheteur Vinted — Italie | D12: SALOMON X Ultra 5 Mid GTX P.44 | E12: 100 | F12: Virement Vinted | G12: Vinted | H12: Vinted — vendue le 12/08/2026, expédiée le 14/08/2026 (Mondial Relay) | I12: Achat-revente | J12: =IF(B12="","",IFERROR(RIGHT(B12,4)&" T"&ROUNDUP(VALUE(MID(B12,4,2))/3,0),"")) | K12: Fonds retenus par Vinted. Relèvera du 4e trimestre 2026.
A13: =IF(B13="","",ROW()-5) | B13: 10/09/2026 | C13: « Calvimo » — pseudonyme Vinted | D13: NEW BALANCE GS 1906 Alkaline Green P.38½ | E13: 99 | F13: Virement Vinted | G13: Vinted | H13: Achat : FB2026-43716 lot n°199 | I13: Achat-revente | J13: =IF(B13="","",IFERROR(RIGHT(B13,4)&" T"&ROUNDUP(VALUE(MID(B13,4,2))/3,0),"")) | K13: À BASCULER dans le registre le jour du virement, pas avant.
A14: =IF(B14="","",ROW()-5) | B14: 10/09/2026 | C14: « amaliagogoi » — pseudonyme Vinted | D14: HAVAIANAS Slim 35/36 — 1 paire | E14: 15 | F14: Virement Vinted | G14: Vinted | H14: Achat : FB2026-5844 lot n°120 | I14: Achat-revente | J14: =IF(B14="","",IFERROR(RIGHT(B14,4)&" T"&ROUNDUP(VALUE(MID(B14,4,2))/3,0),"")) | K14: UBER : à partir du 4e trimestre 2026 (octobre), l'URSSAF est prélevée directement par Uber — ne pas la payer deux fois. Organisation à définir.
A15: =IF(B15="","",ROW()-5) | B15: 3e trimestre 2026 | C15: Divers clients | D15: Livraisons Uber — prestations de services diverses | E15: 40 | F15: Virement Uber | G15: Uber | H15: Relevé de paiements Uber — déclaré au 3e trimestre 2026 | I15: Prestation de services | J15: 2026 T3 | K15: DÉCLARATION URSSAF
A16: =IF(B16="","",ROW()-5) | B16: 23/10/2026 | C16: Hiflow | D16: Convoyages automobiles | E16: 67 | F16: Virement Hiflow | G16: Hiflow | H16: Facture Hiflow n°HIFNACIZR2026-S-3147 du 16/10/2026 — virement 161,80 € dont 94,80 € de frais remboursés (débours, hors CA) | I16: Convoyage automobile | J16: =IF(B16="","",IFERROR(RIGHT(B16,4)&" T"&ROUNDUP(VALUE(MID(B16,4,2))/3,0),"")) | K16: Le CA déclaré est le montant ENCAISSÉ sur la période, pas facturé.
A17: =IF(B17="","",ROW()-5) | J17: =IF(B17="","",IFERROR(RIGHT(B17,4)&" T"&ROUNDUP(VALUE(MID(B17,4,2))/3,0),"")) | K17: Une vente d'août encaissée en septembre se déclare en septembre.
A18: =IF(B18="","",ROW()-5) | J18: =IF(B18="","",IFERROR(RIGHT(B18,4)&" T"&ROUNDUP(VALUE(MID(B18,4,2))/3,0),"")) | K18: Filtrer la colonne « Date d'encaissement » pour isoler le trimestre.
A19: =IF(B19="","",ROW()-5) | J19: =IF(B19="","",IFERROR(RIGHT(B19,4)&" T"&ROUNDUP(VALUE(MID(B19,4,2))/3,0),"")) | K19: 3e trimestre 2026 : 627 € déclarés (587 € de revente + 40 € de prestation), 81 € d'URSSAF payés.
A20: =IF(B20="","",ROW()-5) | J20: =IF(B20="","",IFERROR(RIGHT(B20,4)&" T"&ROUNDUP(VALUE(MID(B20,4,2))/3,0),"")) | K20: Les 206,82 € d'apports personnels n'en font PAS partie : ce ne sont pas des recettes.
A21: =IF(B21="","",ROW()-5) | J21: =IF(B21="","",IFERROR(RIGHT(B21,4)&" T"&ROUNDUP(VALUE(MID(B21,4,2))/3,0),"")) | K21: VENTES EN ESPÈCES — CE QU'IL FAUT GARDER
A22: =IF(B22="","",ROW()-5) | J22: =IF(B22="","",IFERROR(RIGHT(B22,4)&" T"&ROUNDUP(VALUE(MID(B22,4,2))/3,0),"")) | K22: Légal sans limite entre un professionnel et un particulier résidant en France jusqu'à 1 000 €
A23: =IF(B23="","",ROW()-5) | J23: =IF(B23="","",IFERROR(RIGHT(B23,4)&" T"&ROUNDUP(VALUE(MID(B23,4,2))/3,0),"")) | K23: par transaction (art. L112-6 du code monétaire et financier). Toutes les ventes sont loin du seuil.
A24: =IF(B24="","",ROW()-5) | J24: =IF(B24="","",IFERROR(RIGHT(B24,4)&" T"&ROUNDUP(VALUE(MID(B24,4,2))/3,0),""))
A25: =IF(B25="","",ROW()-5) | J25: =IF(B25="","",IFERROR(RIGHT(B25,4)&" T"&ROUNDUP(VALUE(MID(B25,4,2))/3,0),"")) | K25: La preuve d'une vente en espèces, c'est le registre plus le dépôt bancaire. Trois réflexes :
A26: =IF(B26="","",ROW()-5) | J26: =IF(B26="","",IFERROR(RIGHT(B26,4)&" T"&ROUNDUP(VALUE(MID(B26,4,2))/3,0),"")) | K26: 1. Une note de vente par transaction — date, article, prix, nom de l'acheteur. Un carnet suffit.
A27: =IF(B27="","",ROW()-5) | J27: =IF(B27="","",IFERROR(RIGHT(B27,4)&" T"&ROUNDUP(VALUE(MID(B27,4,2))/3,0),"")) | K27: 2. Déposer sur le compte professionnel, pas sur le compte personnel : le détour brouille la piste.
A28: =IF(B28="","",ROW()-5) | J28: =IF(B28="","",IFERROR(RIGHT(B28,4)&" T"&ROUNDUP(VALUE(MID(B28,4,2))/3,0),"")) | K28: 3. Déposer par montants qui recoupent le registre, pour que le relevé confirme les lignes. | L28: 80
A29: =IF(B29="","",ROW()-5) | J29: =IF(B29="","",IFERROR(RIGHT(B29,4)&" T"&ROUNDUP(VALUE(MID(B29,4,2))/3,0),"")) | K29: Baskets NIKE Air Max Moto 2K P.44.5 — gardées, 09/08/2026 | L29: 70
A30: =IF(B30="","",ROW()-5) | J30: =IF(B30="","",IFERROR(RIGHT(B30,4)&" T"&ROUNDUP(VALUE(MID(B30,4,2))/3,0),"")) | K30: Pompe ROBBY VP550W ligne 131 — gardée, 26/07/2026
A31: =IF(B31="","",ROW()-5) | J31: =IF(B31="","",IFERROR(RIGHT(B31,4)&" T"&ROUNDUP(VALUE(MID(B31,4,2))/3,0),"")) | K31: Booster High Class MEGA Dream ex M2a — gardé, 03/08/2026
A32: =IF(B32="","",ROW()-5) | J32: =IF(B32="","",IFERROR(RIGHT(B32,4)&" T"&ROUNDUP(VALUE(MID(B32,4,2))/3,0),""))
A33: =IF(B33="","",ROW()-5) | J33: =IF(B33="","",IFERROR(RIGHT(B33,4)&" T"&ROUNDUP(VALUE(MID(B33,4,2))/3,0),"")) | K33: Un micro-entrepreneur ne peut pas se vendre à lui-même : il n'y a pas deux personnes juridiques.
A34: =IF(B34="","",ROW()-5) | J34: =IF(B34="","",IFERROR(RIGHT(B34,4)&" T"&ROUNDUP(VALUE(MID(B34,4,2))/3,0),"")) | K34: Reprendre un article pour soi n'est pas une recette — aucun chiffre d'affaires, donc aucune URSSAF.
A35: =IF(B35="","",ROW()-5) | J35: =IF(B35="","",IFERROR(RIGHT(B35,4)&" T"&ROUNDUP(VALUE(MID(B35,4,2))/3,0),"")) | K35: Verser de l'argent de son compte personnel vers le compte pro est un APPORT, pas un encaissement.
A36: =IF(B36="","",ROW()-5) | J36: =IF(B36="","",IFERROR(RIGHT(B36,4)&" T"&ROUNDUP(VALUE(MID(B36,4,2))/3,0),"")) | K36: Ces lignes se notent en sortie au registre des objets mobiliers, jamais au livre des recettes.
A37: =IF(B37="","",ROW()-5) | J37: =IF(B37="","",IFERROR(RIGHT(B37,4)&" T"&ROUNDUP(VALUE(MID(B37,4,2))/3,0),""))
A38: =IF(B38="","",ROW()-5) | J38: =IF(B38="","",IFERROR(RIGHT(B38,4)&" T"&ROUNDUP(VALUE(MID(B38,4,2))/3,0),""))
A39: =IF(B39="","",ROW()-5) | J39: =IF(B39="","",IFERROR(RIGHT(B39,4)&" T"&ROUNDUP(VALUE(MID(B39,4,2))/3,0),""))
A40: =IF(B40="","",ROW()-5) | J40: =IF(B40="","",IFERROR(RIGHT(B40,4)&" T"&ROUNDUP(VALUE(MID(B40,4,2))/3,0),""))
...

Sheet Par trimestre
A1: Chiffre d'affaires par trimestre — calculé depuis le livre des recettes
A2: Montants encaissés, par date d'encaissement. URSSAF : 12,4 % achat-revente, 21,3 % prestations et convoyage (taux à confirmer). Livraisons Uber : URSSAF prélevée par Uber à partir de 2026 T4.
A4: Année | B4: Trimestre | C4: Période | D4: Déclaration avant le | E4: Achat-revente | F4: Prestation de services (Uber) | G4: Convoyage automobile | H4: Total encaissé | I4: URSSAF à payer (estimation) | J4: URSSAF réellement payée | K4: Observations
A5: 2026 | B5: T3 | C5: juillet – septembre | D5: 31 octobre 2026 | E5: =SUMIFS('Livre des recettes'!$E$6:$E$311,'Livre des recettes'!$I$6:$I$311,"Achat-revente",'Livre des recettes'!$J$6:$J$311,"2026 T3") | F5: =SUMIFS('Livre des recettes'!$E$6:$E$311,'Livre des recettes'!$I$6:$I$311,"Prestation de services",'Livre des recettes'!$J$6:$J$311,"2026 T3") | G5: =SUMIFS('Livre des recettes'!$E$6:$E$311,'Livre des recettes'!$I$6:$I$311,"Convoyage automobile",'Livre des recettes'!$J$6:$J$311,"2026 T3") | H5: =E5+F5+G5 | I5: =ROUND(E5*0.124+G5*0.213+F5*0.213,2) | J5: 81 | K5: Déclaré et payé : 627 € (587 € revente + 40 € Uber).
A6: 2026 | B6: T4 | C6: octobre – décembre | D6: 31 janvier 2027 | E6: =SUMIFS('Livre des recettes'!$E$6:$E$311,'Livre des recettes'!$I$6:$I$311,"Achat-revente",'Livre des recettes'!$J$6:$J$311,"2026 T4") | F6: =SUMIFS('Livre des recettes'!$E$6:$E$311,'Livre des recettes'!$I$6:$I$311,"Prestation de services",'Livre des recettes'!$J$6:$J$311,"2026 T4") | G6: =SUMIFS('Livre des recettes'!$E$6:$E$311,'Livre des recettes'!$I$6:$I$311,"Convoyage automobile",'Livre des recettes'!$J$6:$J$311,"2026 T4") | H6: =E6+F6+G6 | I6: =ROUND(E6*0.124+G6*0.213,2) | K6: En cours. Ballerines Massimo Dutti (50 €) en attente du virement Vinted.
A7: 2026 | C7: Total 2026 | E7: =SUM(E5:E6) | F7: =SUM(F5:F6) | G7: =SUM(G5:G6) | H7: =SUM(H5:H6) | I7: =SUM(I5:I6) | J7: =SUM(J5:J6)
A9: 2027 | B9: T1 | C9: janvier – mars | D9: 30 avril 2027 | E9: =SUMIFS('Livre des recettes'!$E$6:$E$311,'Livre des recettes'!$I$6:$I$311,"Achat-revente",'Livre des recettes'!$J$6:$J$311,"2027 T1") | F9: =SUMIFS('Livre des recettes'!$E$6:$E$311,'Livre des recettes'!$I$6:$I$311,"Prestation de services",'Livre des recettes'!$J$6:$J$311,"2027 T1") | G9: =SUMIFS('Livre des recettes'!$E$6:$E$311,'Livre des recettes'!$I$6:$I$311,"Convoyage automobile",'Livre des recettes'!$J$6:$J$311,"2027 T1") | H9: =E9+F9+G9 | I9: =ROUND(E9*0.124+G9*0.213,2)
A10: 2027 | B10: T2 | C10: avril – juin | D10: 31 juillet 2027 | E10: =SUMIFS('Livre des recettes'!$E$6:$E$311,'Livre des recettes'!$I$6:$I$311,"Achat-revente",'Livre des recettes'!$J$6:$J$311,"2027 T2") | F10: =SUMIFS('Livre des recettes'!$E$6:$E$311,'Livre des recettes'!$I$6:$I$311,"Prestation de services",'Livre des recettes'!$J$6:$J$311,"2027 T2") | G10: =SUMIFS('Livre des recettes'!$E$6:$E$311,'Livre des recettes'!$I$6:$I$311,"Convoyage automobile",'Livre des recettes'!$J$6:$J$311,"2027 T2") | H10: =E10+F10+G10 | I10: =ROUND(E10*0.124+G10*0.213,2)
A11: 2027 | B11: T3 | C11: juillet – septembre | D11: 31 octobre 2027 | E11: =SUMIFS('Livre des recettes'!$E$6:$E$311,'Livre des recettes'!$I$6:$I$311,"Achat-revente",'Livre des recettes'!$J$6:$J$311,"2027 T3") | F11: =SUMIFS('Livre des recettes'!$E$6:$E$311,'Livre des recettes'!$I$6:$I$311,"Prestation de services",'Livre des recettes'!$J$6:$J$311,"2027 T3") | G11: =SUMIFS('Livre des recettes'!$E$6:$E$311,'Livre des recettes'!$I$6:$I$311,"Convoyage automobile",'Livre des recettes'!$J$6:$J$311,"2027 T3") | H11: =E11+F11+G11 | I11: =ROUND(E11*0.124+G11*0.213,2)
A12: 2027 | B12: T4 | C12: octobre – décembre | D12: 31 janvier 2028 | E12: =SUMIFS('Livre des recettes'!$E$6:$E$311,'Livre des recettes'!$I$6:$I$311,"Achat-revente",'Livre des recettes'!$J$6:$J$311,"2027 T4") | F12: =SUMIFS('Livre des recettes'!$E$6:$E$311,'Livre des recettes'!$I$6:$I$311,"Prestation de services",'Livre des recettes'!$J$6:$J$311,"2027 T4") | G12: =SUMIFS('Livre des recettes'!$E$6:$E$311,'Livre des recettes'!$I$6:$I$311,"Convoyage automobile",'Livre des recettes'!$J$6:$J$311,"2027 T4") | H12: =E12+F12+G12 | I12: =ROUND(E12*0.124+G12*0.213,2)
A13: 2027 | C13: Total 2027 | E13: =SUM(E9:E12) | F13: =SUM(F9:F12) | G13: =SUM(G9:G12) | H13: =SUM(H9:H12) | I13: =SUM(I9:I12) | J13: =SUM(J9:J12)
A15: 2028 | B15: T1 | C15: janvier – mars | D15: 30 avril 2028 | E15: =SUMIFS('Livre des recettes'!$E$6:$E$311,'Livre des recettes'!$I$6:$I$311,"Achat-revente",'Livre des recettes'!$J$6:$J$311,"2028 T1") | F15: =SUMIFS('Livre des recettes'!$E$6:$E$311,'Livre des recettes'!$I$6:$I$311,"Prestation de services",'Livre des recettes'!$J$6:$J$311,"2028 T1") | G15: =SUMIFS('Livre des recettes'!$E$6:$E$311,'Livre des recettes'!$I$6:$I$311,"Convoyage automobile",'Livre des recettes'!$J$6:$J$311,"2028 T1") | H15: =E15+F15+G15 | I15: =ROUND(E15*0.124+G15*0.213,2)
A16: 2028 | B16: T2 | C16: avril – juin | D16: 31 juillet 2028 | E16: =SUMIFS('Livre des recettes'!$E$6:$E$311,'Livre des recettes'!$I$6:$I$311,"Achat-revente",'Livre des recettes'!$J$6:$J$311,"2028 T2") | F16: =SUMIFS('Livre des recettes'!$E$6:$E$311,'Livre des recettes'!$I$6:$I$311,"Prestation de services",'Livre des recettes'!$J$6:$J$311,"2028 T2") | G16: =SUMIFS('Livre des recettes'!$E$6:$E$311,'Livre des recettes'!$I$6:$I$311,"Convoyage automobile",'Livre des recettes'!$J$6:$J$311,"2028 T2") | H16: =E16+F16+G16 | I16: =ROUND(E16*0.124+G16*0.213,2)
A17: 2028 | B17: T3 | C17: juillet – septembre | D17: 31 octobre 2028 | E17: =SUMIFS('Livre des recettes'!$E$6:$E$311,'Livre des recettes'!$I$6:$I$311,"Achat-revente",'Livre des recettes'!$J$6:$J$311,"2028 T3") | F17: =SUMIFS('Livre des recettes'!$E$6:$E$311,'Livre des recettes'!$I$6:$I$311,"Prestation de services",'Livre des recettes'!$J$6:$J$311,"2028 T3") | G17: =SUMIFS('Livre des recettes'!$E$6:$E$311,'Livre des recettes'!$I$6:$I$311,"Convoyage automobile",'Livre des recettes'!$J$6:$J$311,"2028 T3") | H17: =E17+F17+G17 | I17: =ROUND(E17*0.124+G17*0.213,2)
A18: 2028 | B18: T4 | C18: octobre – décembre | D18: 31 janvier 2029 | E18: =SUMIFS('Livre des recettes'!$E$6:$E$311,'Livre des recettes'!$I$6:$I$311,"Achat-revente",'Livre des recettes'!$J$6:$J$311,"2028 T4") | F18: =SUMIFS('Livre des recettes'!$E$6:$E$311,'Livre des recettes'!$I$6:$I$311,"Prestation de services",'Livre des recettes'!$J$6:$J$311,"2028 T4") | G18: =SUMIFS('Livre des recettes'!$E$6:$E$311,'Livre des recettes'!$I$6:$I$311,"Convoyage automobile",'Livre des recettes'!$J$6:$J$311,"2028 T4") | H18: =E18+F18+G18 | I18: =ROUND(E18*0.124+G18*0.213,2)
A19: 2028 | C19: Total 2028 | E19: =SUM(E15:E18) | F19: =SUM(F15:F18) | G19: =SUM(G15:G18) | H19: =SUM(H15:H18) | I19: =SUM(I15:I18) | J19: =SUM(J15:J18)

Sheet Registre des achats
A1: Registre des achats — Maison Nsaia
A2: Obligatoire dès lors qu'il y a achat-revente. Une ligne par lot facturé. | I2: TOTAUX
A3: Les lignes en jaune sont incomplètes : la facture reste à retrouver. | I3: Total engagé — marchandise et expédition | J3: =SUM(E6:E350)
I4: dont marchandise | J4: =SUMIF(D6:D350,"<>Frais d'expédition*",E6:E350)
A5: N° | B5: Date de l'achat | C5: Fournisseur | D5: Désignation | E5: Montant TTC | F5: Mode de règlement | G5: Référence de la facture | I5: dont expédition | J5: =SUMIF(D6:D350,"Frais d'expédition*",E6:E350)
A6: =IF(B6="","",ROW()-5) | B6: 26/07/2026 | C6: ERA Enchères Rhône-Alpes | D6: Pompe immergée ROBBY VP550W noir et bleu — produit d'occasion | E6: 35.9 | F6: Carte | G6: 507148 · commande 28-7
A7: =IF(B7="","",ROW()-5) | B7: 26/07/2026 | C7: ERA Enchères Rhône-Alpes | D7: Pompe immergée ROBBY VP550W noir/gris — comme neuf, SOCLE CASSÉ | E7: 28.29 | F7: Carte | G7: 507148 · commande 28-7 | I7: Lots de marchandise inscrits | J7: 40
A8: =IF(B8="","",ROW()-5) | B8: 26/07/2026 | C8: ERA Enchères Rhône-Alpes | D8: Pompe immergée ROBBY VP550W bleu et noir — occasion, NE MARCHE QU'EN MODE AUTO | E8: 19.41 | F8: Carte | G8: 507148 · commande 28-7 | I8: Lignes à compléter — fond jaune | J8: 0
A9: =IF(B9="","",ROW()-5) | B9: 28/07/2026 | C9: ADN Enchères — Lyon | D9: Lot n°120 — Lot de 12 paires de tongs HAVAIANAS fuchsia 35/36 — neuf | E9: 100.8 | F9: Carte | G9: FB2026-5844 · bordereau TLE-428-5
A10: =IF(B10="","",ROW()-5) | B10: 28/07/2026 | C10: ADN Enchères — Le Mans | D10: Lot n°168 — Veste en jean ARMANI EXCHANGE T.S — neuve | E10: 25.2 | F10: Carte | G10: FB2026-43717 · bordereau ADN-1708-87
A11: =IF(B11="","",ROW()-5) | B11: 28/07/2026 | C11: ADN Enchères — Le Mans | D11: Lot n°303 — Lot de 4 gilets de flottaison MRS.ERTHA 3-6 ans — neuf | E11: 37.8 | F11: Carte | G11: FB2026-43717 · bordereau ADN-1708-87
A12: =IF(B12="","",ROW()-5) | B12: 28/07/2026 | C12: ADN Enchères — Le Mans | D12: Lot n°7 — Robe SANDRO T.40 — neuve | E12: 37.8 | F12: Carte | G12: FB2026-43716 · bordereau ADN-1707-5
A13: =IF(B13="","",ROW()-5) | B13: 28/07/2026 | C13: ADN Enchères — Le Mans | D13: Lot n°103 — Baskets HOKA P.37 1/3 — neuves | E13: 63 | F13: Carte | G13: FB2026-43716 · bordereau ADN-1707-5
A14: =IF(B14="","",ROW()-5) | B14: 28/07/2026 | C14: ADN Enchères — Le Mans | D14: Lot n°170 — Baskets NIKE Air Max Moto 2K P.44.5 — neuves | E14: 50.4 | F14: Carte | G14: FB2026-43716 · bordereau ADN-1707-5
A15: =IF(B15="","",ROW()-5) | B15: 28/07/2026 | C15: ADN Enchères — Le Mans | D15: Lot n°191 — Chaussures HOGAN P.36 — traces d'essayage | E15: 12.6 | F15: Carte | G15: FB2026-43716 · bordereau ADN-1707-5
A16: =IF(B16="","",ROW()-5) | B16: 28/07/2026 | C16: ADN Enchères — Le Mans | D16: Lot n°199 — NEW BALANCE G19064IK Alkaline Green P.38½ — neuves avec boîte | E16: 75.6 | F16: Carte | G16: FB2026-43716 · bordereau ADN-1707-5
A17: =IF(B17="","",ROW()-5) | B17: 28/07/2026 | C17: ADN Enchères — Le Mans | D17: Lot n°357 — Lot de 2 paires ADIDAS Predator Edge P.48 2/3 — neuves | E17: 37.8 | F17: Carte | G17: FB2026-43716 · bordereau ADN-1707-5
A18: =IF(B18="","",ROW()-5) | B18: 28/07/2026 | C18: ADN Enchères — Le Mans | D18: Lot n°408 — Short BA&SH Fegor T.34 — neuf | E18: 50.4 | F18: Carte | G18: FB2026-43716 · bordereau ADN-1707-5
A19: =IF(B19="","",ROW()-5) | B19: 28/07/2026 | C19: ADN Enchères — Le Mans | D19: Lot n°417 — Jupe midi SONIA RYKIEL T.34 — neuve | E19: 37.8 | F19: Carte | G19: FB2026-43716 · bordereau ADN-1707-5
A20: =IF(B20="","",ROW()-5) | B20: 28/07/2026 | C20: ADN Enchères — Le Mans | D20: Lot n°431 — Sac demi-lune nylon noir KARL LAGERFELD JEANS — neuf avec étiquette | E20: 50.4 | F20: Carte | G20: FB2026-43716 · bordereau ADN-1707-5
... A50: =IF(B50="","",ROW()-5) | B50: 12/08/2026 | C50: ADN Enchères — Lyon | D50: Frais d'expédition — Colissimo Point Relais — assurance et signature | E50: 44.02 | F50: Carte | G50: FF2026-4456 · TLE-C27429
A51: =IF(B51="","",ROW()-5)
A52: =IF(B52="","",ROW()-5)
A53: =IF(B53="","",ROW()-5)
A54: =IF(B54="","",ROW()-5)
A55: =IF(B55="","",ROW()-5)
A56: =IF(B56="","",ROW()-5)
A57: =IF(B57="","",ROW()-5)
A58: =IF(B58="","",ROW()-5)
A59: =IF(B59="","",ROW()-5)
A60: =IF(B60="","",ROW()-5)
A61: =IF(B61="","",ROW()-5)
A62: =IF(B62="","",ROW()-5)
... A350: =IF(B350="","",ROW()-5)

Sheet Objets mobiliers
A1: Registre des objets mobiliers — Maison Nsaia
A2: Obligatoire pour l'achat-revente de biens d'occasion — article 321-7 du code pénal. Tenue numérique admise. | M2: SUIVI
A3: Numérotation continue, sans rupture ni suppression. À conserver 5 ans et à présenter à toute réquisition. | M3: Objets inscrits | N3: =COUNTIF(B6:B345,"<>")
M4: Sortis du stock | N4: =COUNT(J6:J345)
A5: N° d'ordre | B5: Date d'acquisition | C5: Vendeur — dénomination | D5: Justificatif d'identité du vendeur | E5: Description de l'objet | F5: Marque / référence | G5: Prix d'achat | H5: Mode de règlement | I5: Date de sortie | J5: Prix de vente | K5: Observations | M5: Prix d'achat cumulé | N5: =SUM(G6:G345)
A6: =IF(B6="","",ROW()-5) | B6: 26/07/2026 | C6: ERA Enchères Rhône-Alpes | D6: Facture | E6: Pompe immergée ROBBY VP550W noir et bleu — produit d'occasion | F6: Robby VP550W — réf. 8350-154 / KRB-3 | G6: 35.9 | H6: Carte | M6: Prix de vente cumulé | N6: =SUM(J6:J345)
A7: =IF(B7="","",ROW()-5) | B7: 26/07/2026 | C7: ERA Enchères Rhône-Alpes | D7: Facture | E7: Pompe immergée ROBBY VP550W noir/gris — comme neuf, SOCLE CASSÉ | F7: Robby VP550W — réf. 10300-238 / OE-4 | G7: 28.29 | H7: Carte | K7: Socle cassé — défaut à déclarer dans l'annonce
A8: =IF(B8="","",ROW()-5) | B8: 26/07/2026 | C8: ERA Enchères Rhône-Alpes | D8: Facture | E8: Pompe immergée ROBBY VP550W bleu et noir — occasion, NE MARCHE QU'EN MODE AUTO | F8: Robby VP550W — réf. 9326-371 / JC-7 | G8: 19.41 | H8: Carte | I8: 13/08/2026 | K8: PRÉLÈVEMENT PERSONNEL — gardée, hors chiffre d'affaires. Ne fonctionne qu'en mode automatique. Date de sortie à confirmer : c'est celle où la décision a été prise, pas celle de l'achat.
A9: =IF(B9="","",ROW()-5) | B9: 28/07/2026 | C9: ADN Enchères — Lyon | D9: Facture — opérateur de ventes volontaires agréé | E9: Lot de 12 paires de tongs HAVAIANAS fuchsia 35/36 — neuf | F9: Havaianas | G9: 100.8 | H9: Carte | I9: 10/08/2026 | J9: 43 | K9: Sortie partielle : 3 paires sur 12 vendues sur Vinted (2 × 14 € encaissées le 10/08, 1 × 15 € encaissée le 10/09) — 9 restent en stock
A10: =IF(B10="","",ROW()-5) | B10: 28/07/2026 | C10: ADN Enchères — Le Mans | D10: Facture — opérateur de ventes volontaires agréé | E10: Veste en jean ARMANI EXCHANGE T.S — neuve | F10: Armani Exchange | G10: 25.2 | H10: Carte | I10: 09/08/2026 | J10: 50 | K10: Vendu à Mme Aouimeur Siham
A11: =IF(B11="","",ROW()-5) | B11: 28/07/2026 | C11: ADN Enchères — Le Mans | D11: Facture — opérateur de ventes volontaires agréé | E11: Lot de 4 gilets de flottaison MRS.ERTHA 3-6 ans — neuf | F11: Mrs.Ertha | G11: 37.8 | H11: Carte
A12: =IF(B12="","",ROW()-5) | B12: 28/07/2026 | C12: ADN Enchères — Le Mans | D12: Facture — opérateur de ventes volontaires agréé | E12: Robe SANDRO T.40 — neuve | F12: Sandro | G12: 37.8 | H12: Carte
A13: =IF(B13="","",ROW()-5) | B13: 28/07/2026 | C13: ADN Enchères — Le Mans | D13: Facture — opérateur de ventes volontaires agréé | E13: Baskets HOKA P.37 1/3 — neuves | F13: Hoka | G13: 63 | H13: Carte | I13: 09/08/2026 | K13: PRÉLÈVEMENT PERSONNEL — gardées, hors chiffre d'affaires
A14: =IF(B14="","",ROW()-5) | B14: 28/07/2026 | C14: ADN Enchères — Le Mans | D14: Facture — opérateur de ventes volontaires agréé | E14: Baskets NIKE Air Max Moto 2K P.44.5 — neuves | F14: Nike | G14: 50.4 | H14: Carte | I14: 09/08/2026 | K14: PRÉLÈVEMENT PERSONNEL — gardées, hors chiffre d'affaires
A15: =IF(B15="","",ROW()-5) | B15: 28/07/2026 | C15: ADN Enchères — Le Mans | D15: Facture — opérateur de ventes volontaires agréé | E15: Chaussures HOGAN P.36 — traces d'essayage | F15: Hogan | G15: 12.6 | H15: Carte
A16: =IF(B16="","",ROW()-5) | B16: 28/07/2026 | C16: ADN Enchères — Le Mans | D16: Facture — opérateur de ventes volontaires agréé | E16: NEW BALANCE G19064IK Alkaline Green P.38½ — neuves avec boîte | F16: New Balance | G16: 75.6 | H16: Carte | I16: 10/09/2026 | J16: 99 | K16: Vendue sur Vinted, encaissée le 10/09/2026
A17: =IF(B17="","",ROW()-5) | B17: 28/07/2026 | C17: ADN Enchères — Le Mans | D17: Facture — opérateur de ventes volontaires agréé | E17: Lot de 2 paires ADIDAS Predator Edge P.48 2/3 — neuves | F17: Adidas | G17: 37.8 | H17: Carte
A18: =IF(B18="","",ROW()-5) | B18: 28/07/2026 | C18: ADN Enchères — Le Mans | D18: Facture — opérateur de ventes volontaires agréé | E18: Short BA&SH Fegor T.34 — neuf | F18: ba&sh | G18: 50.4 | H18: Carte
A19: =IF(B19="","",ROW()-5) | B19: 28/07/2026 | C19: ADN Enchères — Le Mans | D19: Facture — opérateur de ventes volontaires agréé | E19: Jupe midi SONIA RYKIEL T.34 — neuve | F19: Sonia Rykiel | G19: 37.8 | H19: Carte
A20: =IF(B20="","",ROW()-5) | B20: 28/07/2026 | C20: ADN Enchères — Le Mans | D20: Facture — opérateur de ventes volontaires agréé | E20: Sac demi-lune nylon noir KARL LAGERFELD JEANS — neuf avec étiquette | F20: Karl Lagerfeld Jeans | G20: 50.4 | H20: Carte | I20: 09/08/2026 | J20: 70 | K20: Vendu à Mme Aouimeur Siham
A21: =IF(B21="","",ROW()-5) | B21: 28/07/2026 | C21: ADN Enchères — Le Mans | D21: Facture — opérateur de ventes volontaires agréé | E21: ADIDAS x STELLA McCARTNEY ASMC Ultraboost 21 P.36 — modèle d'exposition | F21: Adidas x Stella McCartney | G21: 37.8 | H21: Carte
A22: =IF(B22="","",ROW()-5) | B22: 28/07/2026 | C22: ADN Enchères — Le Mans | D22: Facture — opérateur de ventes volontaires agréé | E22: Ballerines MASSIMO DUTTI P.41 — traces d'essayage | F22: Massimo Dutti | G22: 25.2 | H22: Carte | I22: 17/10/2026 | J22: 50 | K22: Vendu sur Vinted à « anavdlr », encaissement en attente
A23: =IF(B23="","",ROW()-5) | B23: 03/08/2026 | C23: ADN Enchères — Lyon | D23: Facture — opérateur de ventes volontaires agréé | E23: NEW BALANCE sneakers P.38 — neuves | F23: New Balance | G23: 38.34 | H23: Carte
A24: =IF(B24="","",ROW()-5) | B24: 03/08/2026 | C24: ADN Enchères — Lyon | D24: Facture — opérateur de ventes volontaires agréé | E24: LACOSTE sneakers P.42 — neuves | F24: Lacoste | G24: 57.51 | H24: Carte | I24: 09/08/2026 | J24: 70 | K24: Vendu à Mme Aouimeur Siham
A25: =IF(B25="","",ROW()-5) | B25: 03/08/2026 | C25: ADN Enchères — Lyon | D25: Facture — opérateur de ventes volontaires agréé | E25: EMPORIO ARMANI baskets P.36 — neuves | F25: Emporio Armani | G25: 51.12 | H25: Carte
A26: =IF(B26="","",ROW()-5) | B26: 03/08/2026 | C26: ADN Enchères — Lyon | D26: Facture — opérateur de ventes volontaires agréé | E26: GEOX baskets P.35 — neuves | F26: Geox | G26: 21.73 | H26: Carte
A27: =IF(B27="","",ROW()-5) | B27: 03/08/2026 | C27: ADN Enchères — Lyon | D27: Facture — opérateur de ventes volontaires agréé | E27: NEW BALANCE baskets montantes P.44 — neuves | F27: New Balance | G27: 51.12 | H27: Carte
A28: =IF(B28="","",ROW()-5) | B28: 03/08/2026 | C28: ADN Enchères — Lyon | D28: Facture — opérateur de ventes volontaires agréé | E28: TOMMY JEANS baskets basses P.40 — neuves | F28: Tommy Jeans | G28: 52.4 | H28: Carte
A29: =IF(B29="","",ROW()-5) | B29: 03/08/2026 | C29: ADN Enchères — Lyon | D29: Facture — opérateur de ventes volontaires agréé | E29: PHILIPP PLEIN SPORT baskets montantes P.40 — neuves | F29: Philipp Plein Sport | G29: 57.51 | H29: Carte
A30: =IF(B30="","",ROW()-5) | B30: 03/08/2026 | C30: ADN Enchères — Lyon | D30: Facture — opérateur de ventes volontaires agréé | E30: PIER ANTONIO GASPARI robe droite bleu marine T.42 — neuve | F30: Pier Antonio Gaspari | G30: 25.56 | H30: Carte
A31: =IF(B31="","",ROW()-5) | B31: 03/08/2026 | C31: ADN Enchères — Lyon | D31: Facture — opérateur de ventes volontaires agréé | E31: ELISABETTA FRANCHI robe asymétrique viscose T.46 IT — neuve | F31: Elisabetta Franchi | G31: 20.45 | H31: Carte
A32: =IF(B32="","",ROW()-5) | B32: 03/08/2026 | C32: ADN Enchères — Lyon | D32: Facture — opérateur de ventes volontaires agréé | E32: CHIARA FERRAGNI robe bustier courte T.M — neuve | F32: Chiara Ferragni | G32: 31.95 | H32: Carte
A33: =IF(B33="","",ROW()-5) | B33: 03/08/2026 | C33: ADN Enchères — Le Mans | D33: Facture — opérateur de ventes volontaires agréé | E33: SALOMON X Ultra 5 Mid GTX P.44 — neuves | F33: Salomon | G33: 76.68 | H33: Carte | I33: 12/08/2026 | J33: 100 | K33: Vendu sur Vinted (Italie), encaissé le 21/08/2026
A34: =IF(B34="","",ROW()-5) | B34: 03/08/2026 | C34: ADN Enchères — Le Mans | D34: Facture — opérateur de ventes volontaires agréé | E34: Lot de 4 toupies BEYBLADE HASBRO | F34: Beyblade — Hasbro | G34: 19.17 | H34: Carte
A35: =IF(B35="","",ROW()-5) | B35: 03/08/2026 | C35: ADN Enchères — Le Mans | D35: Facture — opérateur de ventes volontaires agréé | E35: Lot de 4 toupies BEYBLADE HASBRO | F35: Beyblade — Hasbro | G35: 38.34 | H35: Carte
A36: =IF(B36="","",ROW()-5) | B36: 03/08/2026 | C36: ADN Enchères — Le Mans | D36: Facture — opérateur de ventes volontaires agréé | E36: T-shirt BALENCIAGA T.2 — neuf | F36: Balenciaga | G36: 113.4 | H36: Carte | I36: 09/08/2026 | J36: 155 | K36: Vendu à Mme Aouimeur Siham
A37: =IF(B37="","",ROW()-5) | B37: 03/08/2026 | C37: ADN Enchères — Le Mans | D37: Facture — opérateur de ventes volontaires agréé | E37: Blazer noir KARL LAGERFELD T.36 FR — neuf avec étiquette | F37: Karl Lagerfeld | G37: 50.4 | H37: Carte
A38: =IF(B38="","",ROW()-5) | B38: 03/08/2026 | C38: Meccha Japan | D38: Facture | E38: 1 booster box Pokémon MEGA Nihil Zero (Munikis Zero) M3 — 30 boosters de 5 cartes | F38: Pokémon — MEGA Nihil Zero M3 (réf. 4521329432274) | G38: 69.24 | H38: Carte
A39: =IF(B39="","",ROW()-5) | B39: 03/08/2026 | C39: Meccha Japan | D39: Facture | E39: 1 booster Pokémon High Class Pack MEGA Dream ex M2a — 10 cartes dans le booster | F39: Pokémon — High Class MEGA Dream ex M2a (réf. 4521329431925) | G39: 12.95 | H39: Carte | I39: 13/08/2026 | K39: PRÉLÈVEMENT PERSONNEL — gardé, hors chiffre d'affaires. Invendable avec profit : marché 12,99 € pour un coût de 12,95 €. Date de sortie à confirmer.
A40: =IF(B40="","",ROW()-5) | B40: 03/08/2026 | C40: Meccha Japan | D40: Facture | E40: 2 boosters Pokémon MEGA Storm Emeralda M6 — 5 cartes chacun | F40: Pokémon — MEGA Storm Emeralda M6 (réf. 4521329462226) | G40: 12.74 | H40: Carte
...
