Workbook

Sheet Stock complet
A1: Stock complet — coûts établis d'après les factures ADN
A2: Coût réel = adjudication + frais acheteur + frais plateforme + livraison répartie par unité de vente.
A3: Lignes jaunes = prix de vente à établir. Ligne verte = vendue.
A5: Désignation | B5: Coût facturé | C5: Coût réel | D5: Seuil d'équilibre | E5: Prix plancher | F5: PRIX DE VENTE | G5: Marge nette | H5: Rendement | I5: Nb | J5: Coût / art. | K5: Prix / art. | L5: Marge / art. | M5: URSSAF | N5: Carte | O5: Adjugé | P5: Frais acheteur | Q5: Maison | R5: Date | S5: Facture | T5: Lot | U5: Canal | V5: Statut | W5: Priorité | X5: Vendu le | Y5: Unités de vente | Z5: MARGE PAR ANNONCE | AA5: Objectif 25 €
A6: Lot de 20 paires de sandales et tongs RELIFE / TOMMY JEANS — neuf | B6: 56.7 | C6: =$B6+$Y6*Paramètres!$B$13 | D6: =$C6/(1-Paramètres!$B$5-Paramètres!$B$6) | E6: =CEILING($D6*Paramètres!$B$24,1) | F6: 199 | G6: =IF($F6="","",$F6-$C6-$M6-$N6) | H6: =IF($G6="","",$G6/$C6) | I6: 20 | J6: =$C6/$I6 | K6: =IF($F6="","",$F6/$I6) | L6: =IF($G6="","",$G6/$I6) | M6: =IF($F6="","",$F6*(Paramètres!$B$5+Paramètres!$B$6)) | N6: 0 | O6: 45 | P6: 11.7 | Q6: ADN Lyon | R6: 11/08/2026 | S6: FB2026-6354 | T6: 388 | U6: Leboncoin B2B | W6: Février-mars | Y6: 1 | Z6: =IF($G6="","",$G6/$Y6) | AA6: =IF($Z6="","",IF($Z6>=25,"atteint",TEXT(25-$Z6,"0.00")&" € manquants"))
A7: Lot de 2 paires ADIDAS Predator Edge P.48 2/3 — neuves | B7: 37.8 | C7: =$B7+$Y7*Paramètres!$B$13 | D7: =$C7/(1-Paramètres!$B$5-Paramètres!$B$6) | E7: =CEILING($D7*Paramètres!$B$24,1) | F7: 178 | G7: =IF($F7="","",$F7-$C7-$M7-$N7) | H7: =IF($G7="","",$G7/$C7) | I7: 2 | J7: =$C7/$I7 | K7: =IF($F7="","",$F7/$I7) | L7: =IF($G7="","",$G7/$I7) | M7: =IF($F7="","",$F7*(Paramètres!$B$5+Paramètres!$B$6)) | N7: 0 | O7: 30 | P7: 7.8 | Q7: ADN Le Mans | R7: 28/07/2026 | S7: FB2026-43716 | T7: 357 | U7: eBay + Leboncoin | W7: Normal | Y7: 2 | Z7: =IF($G7="","",$G7/$Y7) | AA7: =IF($Z7="","",IF($Z7>=25,"atteint",TEXT(25-$Z7,"0.00")&" € manquants"))
A8: Demi-bottes FORMA Legacy Waterproof T.45 noir — neuves | B8: 63 | C8: =$B8+$Y8*Paramètres!$B$13 | D8: =$C8/(1-Paramètres!$B$5-Paramètres!$B$6-Paramètres!$B$7) | E8: =CEILING($D8*Paramètres!$B$24,1) | F8: 159 | G8: =IF($F8="","",$F8-$C8-$M8-$N8) | H8: =IF($G8="","",$G8/$C8) | I8: 1 | J8: =$C8/$I8 | K8: =IF($F8="","",$F8/$I8) | L8: =IF($G8="","",$G8/$I8) | M8: =IF($F8="","",$F8*(Paramètres!$B$5+Paramètres!$B$6)) | N8: =IF($F8="","",$F8*Paramètres!$B$7) | O8: 50 | P8: 13 | Q8: ADN Le Mans | R8: 10/08/2026 | S8: FB2026-46058 | T8: 162 | U8: Boutique + Leboncoin | W8: Normal | Y8: 1 | Z8: =IF($G8="","",$G8/$Y8) | AA8: =IF($Z8="","",IF($Z8>=25,"atteint",TEXT(25-$Z8,"0.00")&" € manquants"))
A9: Lot de 4 gilets de flottaison MRS.ERTHA 3-6 ans — neuf | B9: 37.8 | C9: =$B9+$Y9*Paramètres!$B$13 | D9: =$C9/(1-Paramètres!$B$5-Paramètres!$B$6) | E9: =CEILING($D9*Paramètres!$B$24,1) | F9: 136 | G9: =IF($F9="","",$F9-$C9-$M9-$N9) | H9: =IF($G9="","",$G9/$C9) | I9: 4 | J9: =$C9/$I9 | K9: =IF($F9="","",$F9/$I9) | L9: =IF($G9="","",$G9/$I9) | M9: =IF($F9="","",$F9*(Paramètres!$B$5+Paramètres!$B$6)) | N9: 0 | O9: 30 | P9: 7.8 | Q9: ADN Le Mans | R9: 28/07/2026 | S9: FB2026-43717 | T9: 303 | U9: Leboncoin + Vinted, 34 €/gilet | W9: URGENT — saisonnier | Y9: 4 | Z9: =IF($G9="","",$G9/$Y9) | AA9: =IF($Z9="","",IF($Z9>=25,"atteint",TEXT(25-$Z9,"0.00")&" € manquants"))
A10: Lot de 12 paires de tongs HAVAIANAS fuchsia 35/36 — neuf | B10: 100.8 | C10: =$B10+$Y10*Paramètres!$B$13 | D10: =$C10/(1-Paramètres!$B$5-Paramètres!$B$6) | E10: =CEILING($D10*Paramètres!$B$24,1) | F10: 208 | G10: =IF($F10="","",$F10-$C10-$M10-$N10) | H10: =IF($G10="","",$G10/$C10) | I10: 12 | J10: =$C10/$I10 | K10: =IF($F10="","",$F10/$I10) | L10: =IF($G10="","",$G10/$I10) | M10: =IF($F10="","",$F10*(Paramètres!$B$5+Paramètres!$B$6)) | N10: 0 | O10: 80 | P10: 20.8 | Q10: ADN Lyon | R10: 28/07/2026 | S10: FB2026-5844 | T10: 120 | U10: Vinted + Leboncoin, à l'unité | W10: URGENT — 10 restent, monter à 18 € | X10: 2 vendues à 14 € le 10/08 | Y10: 12 | Z10: =IF($G10="","",$G10/$Y10) | AA10: =IF($Z10="","",IF($Z10>=25,"atteint",TEXT(25-$Z10,"0.00")&" € manquants"))
A11: ELISABETTA FRANCHI robe asymétrique viscose T.46 IT — neuve | B11: 20.45 | C11: =$B11+$Y11*Paramètres!$B$13 | D11: =$C11/(1-Paramètres!$B$5-Paramètres!$B$6-Paramètres!$B$7) | E11: =CEILING($D11*Paramètres!$B$24,1) | F11: 99 | G11: =IF($F11="","",$F11-$C11-$M11-$N11) | H11: =IF($G11="","",$G11/$C11) | I11: 1 | J11: =$C11/$I11 | K11: =IF($F11="","",$F11/$I11) | L11: =IF($G11="","",$G11/$I11) | M11: =IF($F11="","",$F11*(Paramètres!$B$5+Paramètres!$B$6)) | N11: =IF($F11="","",$F11*Paramètres!$B$7) | O11: 16 | P11: 4.16 | Q11: ADN Lyon | R11: 03/08/2026 | S11: FB2026-5996 | T11: 32 | U11: Boutique | W11: Normal | Y11: 1 | Z11: =IF($G11="","",$G11/$Y11) | AA11: =IF($Z11="","",IF($Z11>=25,"atteint",TEXT(25-$Z11,"0.00")&" € manquants"))
A12: Combinaison de pluie BMW Overall ProRain unisexe XL — neuve | B12: 68.57 | C12: =$B12+$Y12*Paramètres!$B$13 | D12: =$C12/(1-Paramètres!$B$5-Paramètres!$B$6) | E12: =CEILING($D12*Paramètres!$B$24,1) | F12: 139 | G12: =IF($F12="","",$F12-$C12-$M12-$N12) | H12: =IF($G12="","",$G12/$C12) | I12: 1 | J12: =$C12/$I12 | K12: =IF($F12="","",$F12/$I12) | L12: =IF($G12="","",$G12/$I12) | M12: =IF($F12="","",$F12*(Paramètres!$B$5+Paramètres!$B$6)) | N12: 0 | O12: 60 | P12: 8.57 | Q12: ADN Le Mans | R12: 10/08/2026 | S12: FB2026-46060 | T12: 1350 | U12: Leboncoin + Vinted | W12: Normal | Y12: 1 | Z12: =IF($G12="","",$G12/$Y12) | AA12: =IF($Z12="","",IF($Z12>=25,"atteint",TEXT(25-$Z12,"0.00")&" € manquants"))
A13: Chaussures HOGAN P.36 — traces d'essayage | B13: 12.6 | C13: =$B13+$Y13*Paramètres!$B$13 | D13: =$C13/(1-Paramètres!$B$5-Paramètres!$B$6-Paramètres!$B$7) | E13: =CEILING($D13*Paramètres!$B$24,1) | F13: 79 | G13: =IF($F13="","",$F13-$C13-$M13-$N13) | H13: =IF($G13="","",$G13/$C13) | I13: 1 | J13: =$C13/$I13 | K13: =IF($F13="","",$F13/$I13) | L13: =IF($G13="","",$G13/$I13) | M13: =IF($F13="","",$F13*(Paramètres!$B$5+Paramètres!$B$6)) | N13: =IF($F13="","",$F13*Paramètres!$B$7) | O13: 10 | P13: 2.6 | Q13: ADN Le Mans | R13: 28/07/2026 | S13: FB2026-43716 | T13: 191 | U13: Boutique | W13: Normal | Y13: 1 | Z13: =IF($G13="","",$G13/$Y13) | AA13: =IF($Z13="","",IF($Z13>=25,"atteint",TEXT(25-$Z13,"0.00")&" € manquants"))
A14: Jupe midi SONIA RYKIEL T.34 — neuve | B14: 37.8 | C14: =$B14+$Y14*Paramètres!$B$13 | D14: =$C14/(1-Paramètres!$B$5-Paramètres!$B$6-Paramètres!$B$7) | E14: =CEILING($D14*Paramètres!$B$24,1) | F14: 99 | G14: =IF($F14="","",$F14-$C14-$M14-$N14) | H14: =IF($G14="","",$G14/$C14) | I14: 1 | J14: =$C14/$I14 | K14: =IF($F14="","",$F14/$I14) | L14: =IF($G14="","",$G14/$I14) | M14: =IF($F14="","",$F14*(Paramètres!$B$5+Paramètres!$B$6)) | N14: =IF($F14="","",$F14*Paramètres!$B$7) | O14: 30 | P14: 7.8 | Q14: ADN Le Mans | R14: 28/07/2026 | S14: FB2026-43716 | T14: 417 | U14: Boutique | W14: Normal | Y14: 1 | Z14: =IF($G14="","",$G14/$Y14) | AA14: =IF($Z14="","",IF($Z14>=25,"atteint",TEXT(25-$Z14,"0.00")&" € manquants"))
A15: Robe SANDRO T.40 — neuve | B15: 37.8 | C15: =$B15+$Y15*Paramètres!$B$13 | D15: =$C15/(1-Paramètres!$B$5-Paramètres!$B$6-Paramètres!$B$7) | E15: =CEILING($D15*Paramètres!$B$24,1) | F15: 89 | G15: =IF($F15="","",$F15-$C15-$M15-$N15) | H15: =IF($G15="","",$G15/$C15) | I15: 1 | J15: =$C15/$I15 | K15: =IF($F15="","",$F15/$I15) | L15: =IF($G15="","",$G15/$I15) | M15: =IF($F15="","",$F15*(Paramètres!$B$5+Paramètres!$B$6)) | N15: =IF($F15="","",$F15*Paramètres!$B$7) | O15: 30 | P15: 7.8 | Q15: ADN Le Mans | R15: 28/07/2026 | S15: FB2026-43716 | T15: 7 | U15: Boutique | W15: Normal | Y15: 1 | Z15: =IF($G15="","",$G15/$Y15) | AA15: =IF($Z15="","",IF($Z15>=25,"atteint",TEXT(25-$Z15,"0.00")&" € manquants"))
A16: Lot de 6 vêtements femme MORGAN T.40 et L — neuf | B16: 37.8 | C16: =$B16+$Y16*Paramètres!$B$13 | D16: =$C16/(1-Paramètres!$B$5-Paramètres!$B$6) | E16: =CEILING($D16*Paramètres!$B$24,1) | F16: 98 | G16: =IF($F16="","",$F16-$C16-$M16-$N16) | H16: =IF($G16="","",$G16/$C16) | I16: 6 | J16: =$C16/$I16 | K16: =IF($F16="","",$F16/$I16) | L16: =IF($G16="","",$G16/$I16) | M16: =IF($F16="","",$F16*(Paramètres!$B$5+Paramètres!$B$6)) | N16: 0 | O16: 30 | P16: 7.8 | Q16: ADN Le Mans | R16: 10/08/2026 | S16: FB2026-46056 | T16: 279 | U16: Leboncoin + eBay, à l'unité | W16: Normal | Y16: 6 | Z16: =IF($G16="","",$G16/$Y16) | AA16: =IF($Z16="","",IF($Z16>=25,"atteint",TEXT(25-$Z16,"0.00")&" € manquants"))
A17: ADIDAS Yeezy 700 V3 Mono Safflower T.38 — occasion | B17: 63 | C17: =$B17+$Y17*Paramètres!$B$13 | D17: =$C17/(1-Paramètres!$B$5-Paramètres!$B$6) | E17: =CEILING($D17*Paramètres!$B$24,1) | F17: 105 | G17: =IF($F17="","",$F17-$C17-$M17-$N17) | H17: =IF($G17="","",$G17/$C17) | I17: 1 | J17: =$C17/$I17 | K17: =IF($F17="","",$F17/$I17) | L17: =IF($G17="","",$G17/$I17) | M17: =IF($F17="","",$F17*(Paramètres!$B$5+Paramètres!$B$6)) | N17: 0 | O17: 50 | P17: 13 | Q17: ADN Le Mans | R17: 10/08/2026 | S17: FB2026-46056 | T17: 8 | U17: Vinted, authentification | W17: Après authentification | Y17: 1 | Z17: =IF($G17="","",$G17/$Y17) | AA17: =IF($Z17="","",IF($Z17>=25,"atteint",TEXT(25-$Z17,"0.00")&" € manquants"))
A18: T-shirt BALENCIAGA T.2 — neuf | B18: 113.4 | C18: =$B18+$Y18*Paramètres!$B$13 | D18: =$C18/(1-Paramètres!$B$5-Paramètres!$B$6) | E18: =CEILING($D18*Paramètres!$B$24,1) | F18: 155 | G18: =IF($F18="","",$F18-$C18-$M18-$N18) | H18: =IF($G18="","",$G18/$C18) | I18: 1 | J18: =$C18/$I18 | K18: =IF($F18="","",$F18/$I18) | L18: =IF($G18="","",$G18/$I18) | M18: =IF($F18="","",$F18*(Paramètres!$B$5+Paramètres!$B$6)) | N18: 0 | O18: 90 | P18: 23.4 | Q18: ADN Le Mans | R18: 03/08/2026 | S18: FB2026-44194 | T18: 9 | U18: vendu | W18: VENDU | X18: VENDU | Y18: 1 | Z18: =IF($G18="","",$G18/$Y18) | AA18: =IF($Z18="","",IF($Z18>=25,"atteint",TEXT(25-$Z18,"0.00")&" € manquants"))
A19: ADIDAS x STELLA McCARTNEY ASMC Ultraboost 21 P.36 — modèle d'exposition | B19: 37.8 | C19: =$B19+$Y19*Paramètres!$B$13 | D19: =$C19/(1-Paramètres!$B$5-Paramètres!$B$6-Paramètres!$B$7) | E19: =CEILING($D19*Paramètres!$B$24,1) | F19: 79 | G19: =IF($F19="","",$F19-$C19-$M19-$N19) | H19: =IF($G19="","",$G19/$C19) | I19: 1 | J19: =$C19/$I19 | K19: =IF($F19="","",$F19/$I19) | L19: =IF($G19="","",$G19/$I19) | M19: =IF($F19="","",$F19*(Paramètres!$B$5+Paramètres!$B$6)) | N19: =IF($F19="","",$F19*Paramètres!$B$7) | O19: 30 | P19: 7.8 | Q19: ADN Le Mans | R19: 28/07/2026 | S19: FB2026-43716 | T19: 434 | U19: Boutique | W19: Normal | Y19: 1 | Z19: =IF($G19="","",$G19/$Y19) | AA19: =IF($Z19="","",IF($Z19>=25,"atteint",TEXT(25-$Z19,"0.00")&" € manquants"))
A20: Blazer noir KARL LAGERFELD T.36 FR — neuf avec étiquette | B20: 50.4 | C20: =$B20+$Y20*Paramètres!$B$13 | D20: =$C20/(1-Paramètres!$B$5-Paramètres!$B$6-Paramètres!$B$7) | E20: =CEILING($D20*Paramètres!$B$24,1) | F20: 91 | G20: =IF($F20="","",$F20-$C20-$M20-$N20) | H20: =IF($G20="","",$G20/$C20) | I20: 1 | J20: =$C20/$I20 | K20: =IF($F20="","",$F20/$I20) | L20: =IF($G20="","",$G20/$I20) | M20: =IF($F20="","",$F20*(Paramètres!$B$5+Paramètres!$B$6)) | N20: =IF($F20="","",$F20*Paramètres!$B$7) | O20: 40 | P20: 10.4 | Q20: ADN Le Mans | R20: 03/08/2026 | S20: FB2026-44194 | T20: 229 | U20: Boutique | W20: Normal | Y20: 1 | Z20: =IF($G20="","",$G20/$Y20) | AA20: =IF($Z20="","",IF($Z20>=25,"atteint",TEXT(25-$Z20,"0.00")&" € manquants"))
A21: PHILIPP PLEIN SPORT baskets montantes P.40 — neuves | B21: 57.51 | C21: =$B21+$Y21*Paramètres!$B$13 | D21: =$C21/(1-Paramètres!$B$5-Paramètres!$B$6) | E21: =CEILING($D21*Paramètres!$B$24,1) | F21: 95 | G21: =IF($F21="","",$F21-$C21-$M21-$N21) | H21: =IF($G21="","",$G21/$C21) | I21: 1 | J21: =$C21/$I21 | K21: =IF($F21="","",$F21/$I21) | L21: =IF($G21="","",$G21/$I21) | M21: =IF($F21="","",$F21*(Paramètres!$B$5+Paramètres!$B$6)) | N21: 0 | O21: 45 | P21: 11.7 | Q21: ADN Lyon | R21: 03/08/2026 | S21: FB2026-6023 | T21: 159 | U21: Leboncoin + eBay | W21: Plafonné par le marché | Y21: 1 | Z21: =IF($G21="","",$G21/$Y21) | AA21: =IF($Z21="","",IF($Z21>=25,"atteint",TEXT(25-$Z21,"0.00")&" € manquants"))
A22: CHIARA FERRAGNI robe bustier courte T.M — neuve | B22: 31.95 | C22: =$B22+$Y22*Paramètres!$B$13 | D22: =$C22/(1-Paramètres!$B$5-Paramètres!$B$6-Paramètres!$B$7) | E22: =CEILING($D22*Paramètres!$B$24,1) | F22: 69 | G22: =IF($F22="","",$F22-$C22-$M22-$N22) | H22: =IF($G22="","",$G22/$C22) | I22: 1 | J22: =$C22/$I22 | K22: =IF($F22="","",$F22/$I22) | L22: =IF($G22="","",$G22/$I22) | M22: =IF($F22="","",$F22*(Paramètres!$B$5+Paramètres!$B$6)) | N22: =IF($F22="","",$F22*Paramètres!$B$7) | O22: 25 | P22: 6.5 | Q22: ADN Lyon | R22: 03/08/2026 | S22: FB2026-5996 | T22: 123 | U22: Boutique + Leboncoin | W22: Normal | Y22: 1 | Z22: =IF($G22="","",$G22/$Y22) | AA22: =IF($Z22="","",IF($Z22>=25,"atteint",TEXT(25-$Z22,"0.00")&" € manquants"))
A23: PIER ANTONIO GASPARI robe droite bleu marine T.42 — neuve | B23: 25.56 | C23: =$B23+$Y23*Paramètres!$B$13 | D23: =$C23/(1-Paramètres!$B$5-Paramètres!$B$6-Paramètres!$B$7) | E23: =CEILING($D23*Paramètres!$B$24,1) | F23: 62 | G23: =IF($F23="","",$F23-$C23-$M23-$N23) | H23: =IF($G23="","",$G23/$C23) | I23: 1 | J23: =$C23/$I23 | K23: =IF($F23="","",$F23/$I23) | L23: =IF($G23="","",$G23/$I23) | M23: =IF($F23="","",$F23*(Paramètres!$B$5+Paramètres!$B$6)) | N23: =IF($F23="","",$F23*Paramètres!$B$7) | O23: 20 | P23: 5.2 | Q23: ADN Lyon | R23: 03/08/2026 | S23: FB2026-5996 | T23: 29 | U23: Boutique + Leboncoin | W23: Normal | Y23: 1 | Z23: =IF($G23="","",$G23/$Y23) | AA23: =IF($Z23="","",IF($Z23>=25,"atteint",TEXT(25-$Z23,"0.00")&" € manquants"))
A24: Lot de 4 toupies BEYBLADE HASBRO | B24: 19.17 | C24: =$B24+$Y24*Paramètres!$B$13 | D24: =$C24/(1-Paramètres!$B$5-Paramètres!$B$6) | E24: =CEILING($D24*Paramètres!$B$24,1) | F24: 55 | G24: =IF($F24="","",$F24-$C24-$M24-$N24) | H24: =IF($G24="","",$G24/$C24) | I24: 4 | J24: =$C24/$I24 | K24: =IF($F24="","",$F24/$I24) | L24: =IF($G24="","",$G24/$I24) | M24: =IF($F24="","",$F24*(Paramètres!$B$5+Paramètres!$B$6)) | N24: 0 | O24: 15 | P24: 3.9 | Q24: ADN Le Mans | R24: 03/08/2026 | S24: FB2026-44192 | T24: 159 | U24: Leboncoin + eBay, en lot | W24: Normal | Y24: 1 | Z24: =IF($G24="","",$G24/$Y24) | AA24: =IF($Z24="","",IF($Z24>=25,"atteint",TEXT(25-$Z24,"0.00")&" € manquants"))
A25: Ballerines MASSIMO DUTTI P.41 — traces d'essayage | B25: 25.2 | C25: =$B25+$Y25*Paramètres!$B$13 | D25: =$C25/(1-Paramètres!$B$5-Paramètres!$B$6) | E25: =CEILING($D25*Paramètres!$B$24,1) | F25: 50 | G25: =IF($F25="","",$F25-$C25-$M25-$N25) | H25: =IF($G25="","",$G25/$C25) | I25: 1 | J25: =$C25/$I25 | K25: =IF($F25="","",$F25/$I25) | L25: =IF($G25="","",$G25/$I25) | M25: =IF($F25="","",$F25*(Paramètres!$B$5+Paramètres!$B$6)) | N25: 0 | O25: 20 | P25: 5.2 | Q25: ADN Le Mans | R25: 28/07/2026 | S25: FB2026-43716 | T25: 439 | U25: Vinted, Espagne — non encaissé | W25: VENDUE, en attente | X25: 17/10/2026 | Y25: 1 | Z25: =IF($G25="","",$G25/$Y25) | AA25: =IF($Z25="","",IF($Z25>=25,"atteint",TEXT(25-$Z25,"0.00")&" € manquants"))
A26: GEOX baskets P.35 — neuves | B26: 21.73 | C26: =$B26+$Y26*Paramètres!$B$13 | D26: =$C26/(1-Paramètres!$B$5-Paramètres!$B$6) | E26: =CEILING($D26*Paramètres!$B$24,1) | F26: 54 | G26: =IF($F26="","",$F26-$C26-$M26-$N26) | H26: =IF($G26="","",$G26/$C26) | I26: 1 | J26: =$C26/$I26 | K26: =IF($F26="","",$F26/$I26) | L26: =IF($G26="","",$G26/$I26) | M26: =IF($F26="","",$F26*(Paramètres!$B$5+Paramètres!$B$6)) | N26: 0 | O26: 17 | P26: 4.42 | Q26: ADN Lyon | R26: 03/08/2026 | S26: FB2026-6023 | T26: 155 | U26: Leboncoin + eBay | W26: Plafonné par le marché | Y26: 1 | Z26: =IF($G26="","",$G26/$Y26) | AA26: =IF($Z26="","",IF($Z26>=25,"atteint",TEXT(25-$Z26,"0.00")&" € manquants"))
A27: 1 booster box Pokémon MEGA Nihil Zero (Munikis Zero) M3 — 30 boosters de 5 cartes — 2 lots de 15 à 49 €, blister à photographier avant ouverture | B27: 69.24 | C27: =$B27 | D27: =$C27/(1-Paramètres!$B$5-Paramètres!$B$6) | E27: =CEILING($D27*Paramètres!$B$24,1) | F27: 98 | G27: =IF($F27="","",$F27-$C27-$M27-$N27) | H27: =IF($G27="","",$G27/$C27) | I27: 2 | J27: =$C27/$I27 | K27: =IF($F27="","",$F27/$I27) | L27: =IF($G27="","",$G27/$I27) | M27: =IF($F27="","",$F27*(Paramètres!$B$5+Paramètres!$B$6)) | N27: 0 | Q27: Meccha Japan | R27: 03/08/2026 | S27: #FA429713 | T27: 4521329432274 | U27: Leboncoin, lots de 15 | W27: Normal | Y27: 2 | Z27: =IF($G27="","",$G27/$Y27) | AA27: =IF($Z27="","",IF($Z27>=25,"atteint",TEXT(25-$Z27,"0.00")&" € manquants"))
A28: Veste en jean ARMANI EXCHANGE T.S — neuve | B28: 25.2 | C28: =$B28+$Y28*Paramètres!$B$13 | D28: =$C28/(1-Paramètres!$B$5-Paramètres!$B$6) | E28: =CEILING($D28*Paramètres!$B$24,1) | F28: 50 | G28: =IF($F28="","",$F28-$C28-$M28-$N28) | H28: =IF($G28="","",$G28/$C28) | I28: 1 | J28: =$C28/$I28 | K28: =IF($F28="","",$F28/$I28) | L28: =IF($G28="","",$G28/$I28) | M28: =IF($F28="","",$F28*(Paramètres!$B$5+Paramètres!$B$6)) | N28: 0 | O28: 20 | P28: 5.2 | Q28: ADN Le Mans | R28: 28/07/2026 | S28: FB2026-43717 | T28: 168 | U28: vendu | W28: VENDU | X28: VENDU | Y28: 1 | Z28: =IF($G28="","",$G28/$Y28) | AA28: =IF($Z28="","",IF($Z28>=25,"atteint",TEXT(25-$Z28,"0.00")&" € manquants"))
A29: Short BA&SH Fegor T.34 — neuf | B29: 50.4 | C29: =$B29+$Y29*Paramètres!$B$13 | D29: =$C29/(1-Paramètres!$B$5-Paramètres!$B$6-Paramètres!$B$7) | E29: =CEILING($D29*Paramètres!$B$24,1) | F29: 75 | G29: =IF($F29="","",$F29-$C29-$M29-$N29) | H29: =IF($G29="","",$G29/$C29) | I29: 1 | J29: =$C29/$I29 | K29: =IF($F29="","",$F29/$I29) | L29: =IF($G29="","",$G29/$I29) | M29: =IF($F29="","",$F29*(Paramètres!$B$5+Paramètres!$B$6)) | N29: =IF($F29="","",$F29*Paramètres!$B$7) | O29: 40 | P29: 10.4 | Q29: ADN Le Mans | R29: 28/07/2026 | S29: FB2026-43716 | T29: 408 | U29: Boutique | W29: URGENT — saisonnier | Y29: 1 | Z29: =IF($G29="","",$G29/$Y29) | AA29: =IF($Z29="","",IF($Z29>=25,"atteint",TEXT(25-$Z29,"0.00")&" € manquants"))
A30: NEW BALANCE G19064IK Alkaline Green P.38½ — neuves avec boîte | B30: 75.6 | C30: =$B30+$Y30*Paramètres!$B$13 | D30: =$C30/(1-Paramètres!$B$5-Paramètres!$B$6) | E30: =CEILING($D30*Paramètres!$B$24,1) | F30: 99 | G30: =IF($F30="","",$F30-$C30-$M30-$N30) | H30: =IF($G30="","",$G30/$C30) | I30: 1 | J30: =$C30/$I30 | K30: =IF($F30="","",$F30/$I30) | L30: =IF($G30="","",$G30/$I30) | M30: =IF($F30="","",$F30*(Paramètres!$B$5+Paramètres!$B$6)) | N30: 0 | O30: 60 | P30: 15.6 | Q30: ADN Le Mans | R30: 28/07/2026 | S30: FB2026-43716 | T30: 199 | U30: Leboncoin | W30: Liquider | Y30: 1 | Z30: =IF($G30="","",$G30/$Y30) | AA30: =IF($Z30="","",IF($Z30>=25,"atteint",TEXT(25-$Z30,"0.00")&" € manquants"))
A31: SALOMON X Ultra 5 Mid GTX P.44 — neuves | B31: 76.68 | C31: =$B31+$Y31*Paramètres!$B$13 | D31: =$C31/(1-Paramètres!$B$5-Paramètres!$B$6) | E31: =CEILING($D31*Paramètres!$B$24,1) | F31: 100 | G31: =IF($F31="","",$F31-$C31-$M31-$N31) | H31: =IF($G31="","",$G31/$C31) | I31: 1 | J31: =$C31/$I31 | K31: =IF($F31="","",$F31/$I31) | L31: =IF($G31="","",$G31/$I31) | M31: =IF($F31="","",$F31*(Paramètres!$B$5+Paramètres!$B$6)) | N31: 0 | O31: 60 | P31: 15.6 | Q31: ADN Le Mans | R31: 03/08/2026 | S31: FB2026-44192 | T31: 11 | U31: Vinted, Italie — non encaissé | W31: VENDUE, en attente | X31: 12/08/2026 | Y31: 1 | Z31: =IF($G31="","",$G31/$Y31) | AA31: =IF($Z31="","",IF($Z31>=25,"atteint",TEXT(25-$Z31,"0.00")&" € manquants"))
A32: Sac demi-lune nylon noir KARL LAGERFELD JEANS — neuf avec étiquette | B32: 50.4 | C32: =$B32+$Y32*Paramètres!$B$13 | D32: =$C32/(1-Paramètres!$B$5-Paramètres!$B$6) | E32: =CEILING($D32*Paramètres!$B$24,1) | F32: 70 | G32: =IF($F32="","",$F32-$C32-$M32-$N32) | H32: =IF($G32="","",$G32/$C32) | I32: 1 | J32: =$C32/$I32 | K32: =IF($F32="","",$F32/$I32) | L32: =IF($G32="","",$G32/$I32) | M32: =IF($F32="","",$F32*(Paramètres!$B$5+Paramètres!$B$6)) | N32: 0 | O32: 40 | P32: 10.4 | Q32: ADN Le Mans | R32: 28/07/2026 | S32: FB2026-43716 | T32: 431 | U32: vendu | W32: VENDU | X32: VENDU | Y32: 1 | Z32: =IF($G32="","",$G32/$Y32) | AA32: =IF($Z32="","",IF($Z32>=25,"atteint",TEXT(25-$Z32,"0.00")&" € manquants"))
A33: EMPORIO ARMANI baskets P.36 — neuves | B33: 51.12 | C33: =$B33+$Y33*Paramètres!$B$13 | D33: =$C33/(1-Paramètres!$B$5-Paramètres!$B$6) | E33: =CEILING($D33*Paramètres!$B$24,1) | F33: 69 | G33: =IF($F33="","",$F33-$C33-$M33-$N33) | H33: =IF($G33="","",$G33/$C33) | I33: 1 | J33: =$C33/$I33 | K33: =IF($F33="","",$F33/$I33) | L33: =IF($G33="","",$G33/$I33) | M33: =IF($F33="","",$F33*(Paramètres!$B$5+Paramètres!$B$6)) | N33: 0 | O33: 40 | P33: 10.4 | Q33: ADN Lyon | R33: 03/08/2026 | S33: FB2026-6023 | T33: 150 | U33: Leboncoin | W33: Liquider | Y33: 1 | Z33: =IF($G33="","",$G33/$Y33) | AA33: =IF($Z33="","",IF($Z33>=25,"atteint",TEXT(25-$Z33,"0.00")&" € manquants"))
A34: Lot de 4 toupies BEYBLADE HASBRO | B34: 38.34 | C34: =$B34+$Y34*Paramètres!$B$13 | D34: =$C34/(1-Paramètres!$B$5-Paramètres!$B$6) | E34: =CEILING($D34*Paramètres!$B$24,1) | F34: 55 | G34: =IF($F34="","",$F34-$C34-$M34-$N34) | H34: =IF($G34="","",$G34/$C34) | I34: 4 | J34: =$C34/$I34 | K34: =IF($F34="","",$F34/$I34) | L34: =IF($G34="","",$G34/$I34) | M34: =IF($F34="","",$F34*(Paramètres!$B$5+Paramètres!$B$6)) | N34: 0 | O34: 30 | P34: 7.8 | Q34: ADN Le Mans | R34: 03/08/2026 | S34: FB2026-44192 | T34: 299 | U34: Leboncoin + eBay, en lot | W34: Marge faible | Y34: 1 | Z34: =IF($G34="","",$G34/$Y34) | AA34: =IF($Z34="","",IF($Z34>=25,"atteint",TEXT(25-$Z34,"0.00")&" € manquants"))
A35: NEW BALANCE sneakers P.38 — neuves | B35: 38.34 | C35: =$B35+$Y35*Paramètres!$B$13 | D35: =$C35/(1-Paramètres!$B$5-Paramètres!$B$6) | E35: =CEILING($D35*Paramètres!$B$24,1) | F35: 54 | G35: =IF($F35="","",$F35-$C35-$M35-$N35) | H35: =IF($G35="","",$G35/$C35) | I35: 1 | J35: =$C35/$I35 | K35: =IF($F35="","",$F35/$I35) | L35: =IF($G35="","",$G35/$I35) | M35: =IF($F35="","",$F35*(Paramètres!$B$5+Paramètres!$B$6)) | N35: 0 | O35: 30 | P35: 7.8 | Q35: ADN Lyon | R35: 03/08/2026 | S35: FB2026-6023 | T35: 114 | U35: Leboncoin | W35: Liquider | Y35: 1 | Z35: =IF($G35="","",$G35/$Y35) | AA35: =IF($Z35="","",IF($Z35>=25,"atteint",TEXT(25-$Z35,"0.00")&" € manquants"))
A36: NEW BALANCE baskets montantes P.44 — neuves | B36: 51.12 | C36: =$B36+$Y36*Paramètres!$B$13 | D36: =$C36/(1-Paramètres!$B$5-Paramètres!$B$6) | E36: =CEILING($D36*Paramètres!$B$24,1) | F36: 65 | G36: =IF($F36="","",$F36-$C36-$M36-$N36) | H36: =IF($G36="","",$G36/$C36) | I36: 1 | J36: =$C36/$I36 | K36: =IF($F36="","",$F36/$I36) | L36: =IF($G36="","",$G36/$I36) | M36: =IF($F36="","",$F36*(Paramètres!$B$5+Paramètres!$B$6)) | N36: 0 | O36: 40 | P36: 10.4 | Q36: ADN Lyon | R36: 03/08/2026 | S36: FB2026-6023 | T36: 156 | U36: Leboncoin | W36: Liquider | Y36: 1 | Z36: =IF($G36="","",$G36/$Y36) | AA36: =IF($Z36="","",IF($Z36>=25,"atteint",TEXT(25-$Z36,"0.00")&" € manquants"))
A37: TOMMY JEANS baskets basses P.40 — neuves | B37: 52.4 | C37: =$B37+$Y37*Paramètres!$B$13 | D37: =$C37/(1-Paramètres!$B$5-Paramètres!$B$6) | E37: =CEILING($D37*Paramètres!$B$24,1) | F37: 65 | G37: =IF($F37="","",$F37-$C37-$M37-$N37) | H37: =IF($G37="","",$G37/$C37) | I37: 1 | J37: =$C37/$I37 | K37: =IF($F37="","",$F37/$I37) | L37: =IF($G37="","",$G37/$I37) | M37: =IF($F37="","",$F37*(Paramètres!$B$5+Paramètres!$B$6)) | N37: 0 | O37: 41 | P37: 10.66 | Q37: ADN Lyon | R37: 03/08/2026 | S37: FB2026-6023 | T37: 158 | U37: Leboncoin + eBay | W37: Liquider | Y37: 1 | Z37: =IF($G37="","",$G37/$Y37) | AA37: =IF($Z37="","",IF($Z37>=25,"atteint",TEXT(25-$Z37,"0.00")&" € manquants"))
A38: LACOSTE sneakers P.42 — neuves | B38: 57.51 | C38: =$B38+$Y38*Paramètres!$B$13 | D38: =$C38/(1-Paramètres!$B$5-Paramètres!$B$6) | E38: =CEILING($D38*Paramètres!$B$24,1) | F38: 70 | G38: =IF($F38="","",$F38-$C38-$M38-$N38) | H38: =IF($G38="","",$G38/$C38) | I38: 1 | J38: =$C38/$I38 | K38: =IF($F38="","",$F38/$I38) | L38: =IF($G38="","",$G38/$I38) | M38: =IF($F38="","",$F38*(Paramètres!$B$5+Paramètres!$B$6)) | N38: 0 | O38: 45 | P38: 11.7 | Q38: ADN Lyon | R38: 03/08/2026 | S38: FB2026-6023 | T38: 141 | U38: vendu | W38: VENDU | X38: VENDU | Y38: 1 | Z38: =IF($G38="","",$G38/$Y38) | AA38: =IF($Z38="","",IF($Z38>=25,"atteint",TEXT(25-$Z38,"0.00")&" € manquants"))
A39: Pompe immergée ROBBY VP550W noir et bleu — produit d'occasion | B39: 35.9 | C39: =$B39 | D39: =$C39/(1-Paramètres!$B$5-Paramètres!$B$6) | E39: =CEILING($D39*Paramètres!$B$24,1) | F39: 45 | G39: =IF($F39="","",$F39-$C39-$M39-$N39) | H39: =IF($G39="","",$G39/$C39) | I39: 1 | J39: =$C39/$I39 | K39: =IF($F39="","",$F39/$I39) | L39: =IF($G39="","",$G39/$I39) | M39: =IF($F39="","",$F39*(Paramètres!$B$5+Paramètres!$B$6)) | N39: 0 | Q39: ERA Enchères Rhône-Alpes | R39: 26/07/2026 | S39: 507148 | T39: 84 | U39: Leboncoin, main propre | W39: Normal | Y39: 1 | Z39: =IF($G39="","",$G39/$Y39) | AA39: =IF($Z39="","",IF($Z39>=25,"atteint",TEXT(25-$Z39,"0.00")&" € manquants"))
A40: Pompe immergée ROBBY VP550W noir/gris — comme neuf, SOCLE CASSÉ | B40: 28.29 | C40: =$B40 | D40: =$C40/(1-Paramètres!$B$5-Paramètres!$B$6) | E40: =CEILING($D40*Paramètres!$B$24,1) | F40: 35 | G40: =IF($F40="","",$F40-$C40-$M40-$N40) | H40: =IF($G40="","",$G40/$C40) | I40: 1 | J40: =$C40/$I40 | K40: =IF($F40="","",$F40/$I40) | L40: =IF($G40="","",$G40/$I40) | M40: =IF($F40="","",$F40*(Paramètres!$B$5+Paramètres!$B$6)) | N40: 0 | Q40: ERA Enchères Rhône-Alpes | R40: 26/07/2026 | S40: 507148 | T40: 122 | U40: Leboncoin, main propre | W40: Marge faible | Y40: 1 | Z40: =IF($G40="","",$G40/$Y40) | AA40: =IF($Z40="","",IF($Z40>=25,"atteint",TEXT(25-$Z40,"0.00")&" € manquants"))
A41: 2 boosters Pokémon MEGA Storm Emeralda M6 — 5 cartes chacun — set sorti le 31/07/2026, publier vite | B41: 12.74 | C41: =$B41 | D41: =$C41/(1-Paramètres!$B$5-Paramètres!$B$6) | E41: =CEILING($D41*Paramètres!$B$24,1) | F41: 19 | G41: =IF($F41="","",$F41-$C41-$M41-$N41) | H41: =IF($G41="","",$G41/$C41) | I41: 1 | J41: =$C41/$I41 | K41: =IF($F41="","",$F41/$I41) | L41: =IF($G41="","",$G41/$I41) | M41: =IF($F41="","",$F41*(Paramètres!$B$5+Paramètres!$B$6)) | N41: 0 | Q41: Meccha Japan | R41: 03/08/2026 | S41: #FA429713 | T41: 4521329462226 | U41: Leboncoin, lot de 2 | W41: Normal | Y41: 1 | Z41: =IF($G41="","",$G41/$Y41) | AA41: =IF($Z41="","",IF($Z41>=25,"atteint",TEXT(25-$Z41,"0.00")&" € manquants"))
...

Sheet Synthèse
A1: Synthèse
A3: CAPITAL ENGAGÉ
A4: Marchandise ADN | B4: 1637.35
A5: Livraison ADN | B5: =Paramètres!B11
A6: Achats hors ADN (pompes, Pokémon) | B6: 178.53
A7: TOTAL ENGAGÉ | B7: ='Stock complet'!C46
A9: CHIFFRE D'AFFAIRES ET MARGE
A10: Chiffre d'affaires attendu | B10: ='Stock complet'!F46 | C10: hors lots dont le prix reste à établir
A11: − URSSAF + CFP | B11: =-'Stock complet'!M46
A12: − Commission carte | B12: =-'Stock complet'!N46
A13: =Marge brute | B13: ='Stock complet'!G46
A14: − Emballage | B14: =-Paramètres!B20*Paramètres!B21
A15: − Frais fixe carte | B15: =-Paramètres!B8*Paramètres!B21
A16: =Marge avant impôt | B16: =B13+B14+B15
A17: Base imposable | B17: =B10*(1-Paramètres!B16)
A18: − Impôt estimé | B18: =-B17*Paramètres!B17
A19: =CE QUI RESTE | B19: =B16+B18
A21: RENDEMENT
A22: Marge nette / capital engagé | B22: =B19/B7
A23: Articles physiques | B23: ='Stock complet'!I46
A24: Taux de marge nette sur le CA | B24: =B19/B10 | C24: ce qui reste pour 1 € encaissé
A26: CHARGES FIXES — CE QUE LA BOUTIQUE COÛTE AVANT DE VENDRE
A27: Shopify + Claude, aujourd'hui | B27: =Paramètres!B30 | C27: 1 € + 22 €
A28: Shopify + Claude, à partir du 11/11/2026 | B28: =Paramètres!B31 | C28: 36 € + 22 €
A29: Soit par an, à partir de novembre | B29: =Paramètres!B31*12
A30: CA mensuel nécessaire pour les couvrir | B30: =Paramètres!B31/B24 | C30: au taux de marge nette du stock actuel
A31: Marge du stock entier | B31: =B19 | C31: de quoi couvrir combien de mois :
A32: Mois de charges couverts par tout le stock | B32: =B19/Paramètres!B31
A34: À FAIRE
A35: Yeezy 700 V3 : 105 € sous réserve d'authentification. Neuve à 140 € (wehaveit.fr).
A36: CA encaissé : 373 €, pas 493 €. Les Hoka et les Nike sont des prélèvements, pas des ventes.
A37: Toutes les factures sont reçues. 150,50 € de stock prélevé pour usage personnel.
A38: SEUIL D'ÉQUILIBRE : ne jamais vendre en dessous, la vente coûterait de l'argent.
A39: PRIX PLANCHER : 30 % au-dessus du seuil. Le plus bas acceptable, famille comprise.
A40: Ne pas confondre avec le seuil de sourcing de 25 € : celui-là sert à decider d'ACHETER, pas de vendre.
A41: OBJECTIF 25 € DE MARGE PAR VENTE : atteint sur 15 lots, impossible sur 13 — le prix de rue plafonne.
A42: Règle d'achat qui en découle : coût maximum tout compris = prix marché × 0,876 − 25 €.
A43: Sous 121 € de prix marché, cette règle est plus stricte que celle des deux tiers. Au-dessus, c'est l'inverse.
A44: Sous 40 € de prix marché, 25 € de marge sont hors d'atteinte quelle que soit l'enchère. Ne pas miser.

Sheet Paramètres
A1: Paramètres
A2: Cellules jaunes : les seules à modifier.
A4: CHARGES SUR LE CHIFFRE D'AFFAIRES
A5: Cotisations URSSAF (achat-revente BIC) | B5: 0.123 | C5: À confirmer sur autoentrepreneur.urssaf.fr
A6: CFP — formation professionnelle | B6: 0.001
A7: Commission carte Shopify Payments | B7: 0.015 | C7: Boutique uniquement
A8: Frais fixe par transaction carte | B8: 0.25
A10: LIVRAISON DES LOTS
A11: Total des factures de livraison ADN | B11: 127.8 | C11: 5 factures Colissimo Point Relais
A12: Unités de vente reçues d'ADN | B12: 54 | C12: un lot vendu en bloc compte pour 1
A13: Livraison par unité de vente | B13: =B11/B12 | C13: réparti au nombre de colis à expédier
A15: IMPÔT SUR LE REVENU — MICRO-BIC
A16: Abattement forfaitaire | B16: 0.71 | C16: Versement libératoire NON retenu
A17: Tranche marginale du foyer | B17: 0.11 | C17: 0 %, 11 %, 30 %… à ajuster
A19: FRAIS DE VENTE
A20: Emballage par colis | B20: 2
A21: Nombre d'annonces prévues | B21: 40
A23: PLANCHER DE NÉGOCIATION
A24: Coefficient sur le seuil d'équilibre | B24: 1.3 | C24: plancher = seuil × ce coefficient
A26: CHARGES FIXES MENSUELLES
A27: Abonnement Shopify — aujourd'hui | B27: 1 | C27: 1 €/mois jusqu'au 10/11/2026
A28: Abonnement Shopify — à partir du 11/11/2026 | B28: 36 | C28: 432 €/an
A29: Abonnement Claude | B29: 22 | C29: 264 €/an
A30: Total mensuel aujourd'hui | B30: =B27+B29
A31: Total mensuel à partir du 11/11/2026 | B31: =B28+B29 | C31: 696 €/an
A33: CHARGES FIXES ANNUELLES
A34: CFE — cotisation foncière des entreprises | B34: 0 | C34: exonérée en 2026, 200 à 600 €/an à partir de 2027
A36: COMMISSION D'ENCAISSEMENT PAR CANAL
A37: Shopify Payments — taux | B37: 0.015 | C37: le moins cher : canal à privilégier
A38: Shopify Payments — frais fixe | B38: 0.25
A39: PayPal — taux | B39: 0.029 | C39: À RELEVER sur ton compte : Paramètres > Frais marchands
A40: PayPal — frais fixe | B40: 0.35 | C40: À RELEVER — les sources publiques donnent 0,25 à 0,49 €
A41: PayPal — supplément hors zone euro | B41: 0.015 | C41: À RELEVER — s'ajoute au taux ci-dessus
A42: Vinted et Leboncoin en main propre | B42: 0 | C42: aucune commission
A44: Coefficient de marge — Shopify Payments | B44: =1-B5-B6-B37 | C44: marge = prix × ce coefficient − coût − frais fixe
A45: Coefficient de marge — PayPal | B45: =1-B5-B6-B39 | C45: chaque vente encaissée par PayPal coûte ce qui manque
A46: Coefficient de marge — hors carte | B46: =1-B5-B6 | C46: Leboncoin, Vinted, espèces
A47: Écart PayPal / Shopify Payments sur une vente à 89 € | B47: =89*(B39-B37)+(B40-B38) | C47: multiplié par le nombre de ventes encaissées ainsi

Sheet Factures
A1: Factures ADN — relevé intégral
A2: Source de tous les coûts du classeur. À conserver 5 ans.
A4: Facture | B4: Date | C4: Maison | D4: Bordereau | E4: Lot | F4: Désignation | G4: Adjugé | H4: Frais acheteur | I4: Frais plateforme | J4: Total TTC
A5: FB2026-5844 | B5: 28/07/2026 | C5: ADN Lyon | D5: TLE-428-5 | E5: 120 | F5: Lot de 12 paires de tongs HAVAIANAS fuchsia 35/36 — neuf | G5: 80 | H5: 20.8 | I5: 0 | J5: 100.8
A6: FB2026-43717 | B6: 28/07/2026 | C6: ADN Le Mans | D6: ADN-1708-87 | E6: 168 | F6: Veste en jean ARMANI EXCHANGE T.S — neuve | G6: 20 | H6: 5.2 | I6: 0 | J6: 25.2
A7: FB2026-43717 | B7: 28/07/2026 | C7: ADN Le Mans | D7: ADN-1708-87 | E7: 303 | F7: Lot de 4 gilets de flottaison MRS.ERTHA 3-6 ans — neuf | G7: 30 | H7: 7.8 | I7: 0 | J7: 37.8
A8: FB2026-43716 | B8: 28/07/2026 | C8: ADN Le Mans | D8: ADN-1707-5 | E8: 7 | F8: Robe SANDRO T.40 — neuve | G8: 30 | H8: 7.8 | I8: 0 | J8: 37.8
A9: FB2026-43716 | B9: 28/07/2026 | C9: ADN Le Mans | D9: ADN-1707-5 | E9: 103 | F9: Baskets HOKA P.37 1/3 — neuves | G9: 50 | H9: 13 | I9: 0 | J9: 63
A10: FB2026-43716 | B10: 28/07/2026 | C10: ADN Le Mans | D10: ADN-1707-5 | E10: 170 | F10: Baskets NIKE Air Max Moto 2K P.44.5 — neuves | G10: 40 | H10: 10.4 | I10: 0 | J10: 50.4
A11: FB2026-43716 | B11: 28/07/2026 | C11: ADN Le Mans | D11: ADN-1707-5 | E11: 191 | F11: Chaussures HOGAN P.36 — traces d'essayage | G11: 10 | H11: 2.6 | I11: 0 | J11: 12.6
A12: FB2026-43716 | B12: 28/07/2026 | C12: ADN Le Mans | D12: ADN-1707-5 | E12: 199 | F12: NEW BALANCE G19064IK Alkaline Green P.38½ — neuves avec boîte | G12: 60 | H12: 15.6 | I12: 0 | J12: 75.6
A13: FB2026-43716 | B13: 28/07/2026 | C13: ADN Le Mans | D13: ADN-1707-5 | E13: 357 | F13: Lot de 2 paires ADIDAS Predator Edge P.48 2/3 — neuves | G13: 30 | H13: 7.8 | I13: 0 | J13: 37.8
A14: FB2026-43716 | B14: 28/07/2026 | C14: ADN Le Mans | D14: ADN-1707-5 | E14: 408 | F14: Short BA&SH Fegor T.34 — neuf | G14: 40 | H14: 10.4 | I14: 0 | J14: 50.4
A15: FB2026-43716 | B15: 28/07/2026 | C15: ADN Le Mans | D15: ADN-1707-5 | E15: 417 | F15: Jupe midi SONIA RYKIEL T.34 — neuve | G15: 30 | H15: 7.8 | I15: 0 | J15: 37.8
A16: FB2026-43716 | B16: 28/07/2026 | C16: ADN Le Mans | D16: ADN-1707-5 | E16: 431 | F16: Sac demi-lune nylon noir KARL LAGERFELD JEANS — neuf avec étiquette | G16: 40 | H16: 10.4 | I16: 0 | J16: 50.4
... A38: FB2026-6354 | B38: 11/08/2026 | C38: ADN Lyon | D38: TLE-442-121 | E38: 388 | F38: Lot de 20 paires de sandales et tongs RELIFE / TOMMY JEANS — neuf | G38: 45 | H38: 11.7 | I38: 0 | J38: 56.7
F39: TOTAL MARCHANDISE | G39: =SUM(G5:G38) | H39: =SUM(H5:H38) | I39: =SUM(I5:I38) | J39: =SUM(J5:J38)
A41: FACTURES DE LIVRAISON
A42: Facture | B42: Date | C42: Maison | D42: Commande | E42: Désignation | F42: Total TTC
A43: FF2026-4060 | B43: 28/07/2026 | C43: ADN Lyon | D43: TLE-C26638 | E43: Colissimo Point Relais — assurance et signature | F43: 19.9
A44: FF2026-4146 | B44: 03/08/2026 | C44: ADN Lyon | D44: TLE-C26827 | E44: Colissimo Point Relais — assurance et signature | F44: 18.22
A45: FF2026-4160 | B45: 03/08/2026 | C45: ADN Lyon | D45: TLE-C26851 | E45: Colissimo Point Relais — assurance et signature | F45: 29.94
A46: FF2026-32305 | B46: 10/08/2026 | C46: ADN Le Mans | D46: ADN-C208494 | E46: Colissimo Point Relais | F46: 15.72
A47: FF2026-4456 | B47: 12/08/2026 | C47: ADN Lyon | D47: TLE-C27429 | E47: Colissimo Point Relais — assurance et signature | F47: 44.02
E48: TOTAL LIVRAISON | F48: =SUM(F43:F47)
